Workbook
Name InputMode: Results!$CB$2:$CC$3
Name Target: Results!$CD$2:$CE$3
Name Win: Results!$BZ$2:$CA$10

Sheet DATA
A1: experiment_id | B1: input_id | C1: window_sec | D1: overlap_sec | E1: target | F1: input_mode | G1: representation | H1: model | I1: feature_count_before_aggregation | J1: input_feature_count | K1: subjects_total | L1: outer_folds_run | M1: complete_loso | N1: quick_grid | O1: experiment_seconds | P1: n_samples | Q1: n_low | R1: n_high | S1: fold_has_both_classes | T1: accuracy | U1: balanced_accuracy_fixed | V1: macro_precision_fixed | W1: macro_recall_fixed | X1: macro_f1_fixed | Y1: low_precision | Z1: low_recall | AA1: low_f1 | AB1: low_support | AC1: high_precision | AD1: high_recall | AE1: high_f1 | AF1: high_support | AG1: mcc | AH1: tn | AI1: fp | AJ1: fn | AK1: tp | AL1: roc_auc | AM1: average_precision | AN1: bootstrap_repeats | AO1: accuracy_ci_low | AP1: accuracy_ci_high | AQ1: balanced_accuracy_fixed_ci_low | AR1: balanced_accuracy_fixed_ci_high | AS1: macro_f1_fixed_ci_low | AT1: macro_f1_fixed_ci_high | AU1: mcc_ci_low | AV1: mcc_ci_high | AW1: roc_auc_ci_low | AX1: roc_auc_ci_high | AY1: average_precision_ci_low | AZ1: average_precision_ci_high
A2: emognition_features_w60_o30__valence__windowed__hc__svm | B2: emognition_features_w60_o30 | C2: 60 | D2: 30 | E2: valence | F2: windowed | G2: hc | H2: svm | I2: 29 | J2: 29 | K2: 42 | L2: 42 | M2: TRUE | N2: FALSE | O2: 38.537719 | P2: 681 | Q2: 314 | R2: 367 | S2: TRUE | T2: 0.51395007 | U2: 0.51064319 | V2: 0.51065873 | W2: 0.51064319 | X2: 0.51064098 | Y2: 0.47266881 | Z2: 0.46815287 | AA2: 0.4704 | AB2: 314 | AC2: 0.54864865 | AD2: 0.55313351 | AE2: 0.55088195 | AF2: 367 | AG2: 0.021301914 | AH2: 147 | AI2: 167 | AJ2: 164 | AK2: 203 | AL2: 0.51461324 | AM2: 0.5410137 | AN2: 1000 | AO2: 0.46482717 | AP2: 0.56702872 | AQ2: 0.46445563 | AR2: 0.56106732 | AS2: 0.4627526 | AT2: 0.56049871 | AU2: -0.070929127 | AV2: 0.1220085 | AW2: 0.45772893 | AX2: 0.57343042 | AY2: 0.47191945 | AZ2: 0.61631314
A3: emognition_features_w60_o30__valence__windowed__hc__rf | B3: emognition_features_w60_o30 | C3: 60 | D3: 30 | E3: valence | F3: windowed | G3: hc | H3: rf | I3: 29 | J3: 29 | K3: 42 | L3: 42 | M3: TRUE | N3: FALSE | O3: 499.69602 | P3: 681 | Q3: 314 | R3: 367 | S3: TRUE | T3: 0.51835536 | U3: 0.51059112 | V3: 0.51097098 | W3: 0.51059112 | X3: 0.50879631 | Y3: 0.47426471 | Z3: 0.41082803 | AA3: 0.44027304 | AB3: 314 | AC3: 0.54767726 | AD3: 0.61035422 | AE3: 0.57731959 | AF3: 367 | AG3: 0.021558762 | AH3: 129 | AI3: 185 | AJ3: 143 | AK3: 224 | AL3: 0.51801489 | AM3: 0.55565317 | AN3: 1000 | AO3: 0.47125327 | AP3: 0.57473847 | AQ3: 0.47001054 | AR3: 0.55566929 | AS3: 0.46602736 | AT3: 0.55428137 | AU3: -0.060686875 | AV3: 0.11323688 | AW3: 0.46254635 | AX3: 0.57106485 | AY3: 0.4857797 | AZ3: 0.6380809
A4: emognition_features_w60_o30__valence__windowed__hc__knn | B4: emognition_features_w60_o30 | C4: 60 | D4: 30 | E4: valence | F4: windowed | G4: hc | H4: knn | I4: 29 | J4: 29 | K4: 42 | L4: 42 | M4: TRUE | N4: FALSE | O4: 25.715157 | P4: 681 | Q4: 314 | R4: 367 | S4: TRUE | T4: 0.49045521 | U4: 0.48884483 | V4: 0.48889494 | W4: 0.48884483 | X4: 0.48869117 | Y4: 0.44954128 | Z4: 0.46815287 | AA4: 0.45865835 | AB4: 314 | AC4: 0.52824859 | AD4: 0.50953678 | AE4: 0.51872399 | AF4: 367 | AG4: -0.022260182 | AH4: 147 | AI4: 167 | AJ4: 180 | AK4: 187 | AL4: 0.49287995 | AM4: 0.53405478 | AN4: 1000 | AO4: 0.45344753 | AP4: 0.52323838 | AQ4: 0.45190426 | AR4: 0.52054825 | AS4: 0.4513047 | AT4: 0.51940957 | AU4: -0.096245159 | AV4: 0.041063889 | AW4: 0.44733636 | AX4: 0.53428523 | AY4: 0.47622332 | AZ4: 0.59077655
A5: emognition_features_w60_o30__valence__windowed__hc__xgboost | B5: emognition_features_w60_o30 | C5: 60 | D5: 30 | E5: valence | F5: windowed | G5: hc | H5: xgboost | I5: 29 | J5: 29 | K5: 42 | L5: 42 | M5: TRUE | N5: FALSE | O5: 497.6819 | P5: 681 | Q5: 314 | R5: 367 | S5: TRUE | T5: 0.51101322 | U5: 0.50860827 | V5: 0.50859038 | W5: 0.50860827 | X5: 0.50857176 | Y5: 0.47021944 | Z5: 0.47770701 | AA5: 0.47393365 | AB5: 314 | AC5: 0.54696133 | AD5: 0.53950954 | AE5: 0.54320988 | AF5: 367 | AG5: 0.017198643 | AH5: 150 | AI5: 164 | AJ5: 169 | AK5: 198 | AL5: 0.51738142 | AM5: 0.56233728 | AN5: 1000 | AO5: 0.46683463 | AP5: 0.55487828 | AQ5: 0.4637663 | AR5: 0.54954578 | AS5: 0.46351302 | AT5: 0.54939131 | AU5: -0.072723947 | AV5: 0.099383995 | AW5: 0.47166983 | AX5: 0.56092297 | AY5: 0.49936616 | AZ5: 0.64027999
A6: emognition_features_w60_o30__valence__windowed__nvg__svm | B6: emognition_features_w60_o30 | C6: 60 | D6: 30 | E6: valence | F6: windowed | G6: nvg | H6: svm | I6: 48 | J6: 48 | K6: 42 | L6: 42 | M6: TRUE | N6: FALSE | O6: 38.003898 | P6: 681 | Q6: 314 | R6: 367 | S6: TRUE | T6: 0.52863436 | U6: 0.52472709 | V6: 0.5248474 | W6: 0.52472709 | X6: 0.52469467 | Y6: 0.48852459 | Z6: 0.47452229 | AA6: 0.48142165 | AB6: 314 | AC6: 0.56117021 | AD6: 0.57493188 | AE6: 0.5679677 | AF6: 367 | AG6: 0.049574342 | AH6: 149 | AI6: 165 | AJ6: 156 | AK6: 211 | AL6: 0.53006821 | AM6: 0.55324001 | AN6: 1000 | AO6: 0.48442411 | AP6: 0.57345209 | AQ6: 0.48271603 | AR6: 0.56639731 | AS6: 0.48207633 | AT6: 0.56585657 | AU6: -0.034579739 | AV6: 0.13243123 | AW6: 0.47707491 | AX6: 0.58145498 | AY6: 0.49034976 | AZ6: 0.62758301
A7: emognition_features_w60_o30__valence__windowed__nvg__rf | B7: emognition_features_w60_o30 | C7: 60 | D7: 30 | E7: valence | F7: windowed | G7: nvg | H7: rf | I7: 48 | J7: 48 | K7: 42 | L7: 42 | M7: TRUE | N7: FALSE | O7: 493.38964 | P7: 681 | Q7: 314 | R7: 367 | S7: TRUE | T7: 0.53157122 | U7: 0.5240025 | V7: 0.52483301 | W7: 0.5240025 | X7: 0.52247294 | Y7: 0.49084249 | Z7: 0.42675159 | AA7: 0.45655877 | AB7: 314 | AC7: 0.55882353 | AD7: 0.62125341 | AE7: 0.5883871 | AF7: 367 | AG7: 0.048828447 | AH7: 134 | AI7: 180 | AJ7: 139 | AK7: 228 | AL7: 0.54091532 | AM7: 0.56074411 | AN7: 1000 | AO7: 0.48733495 | AP7: 0.57709521 | AQ7: 0.48311135 | AR7: 0.56654759 | AS7: 0.47960741 | AT7: 0.5651671 | AU7: -0.033790807 | AV7: 0.13380939 | AW7: 0.4877165 | AX7: 0.59463301 | AY7: 0.49395235 | AZ7: 0.64975066
A8: emognition_features_w60_o30__valence__windowed__nvg__knn | B8: emognition_features_w60_o30 | C8: 60 | D8: 30 | E8: valence | F8: windowed | G8: nvg | H8: knn | I8: 48 | J8: 48 | K8: 42 | L8: 42 | M8: TRUE | N8: FALSE | O8: 24.359692 | P8: 681 | Q8: 314 | R8: 367 | S8: TRUE | T8: 0.53744493 | U8: 0.53359135 | V8: 0.5337548 | W8: 0.53359135 | X8: 0.53357888 | Y8: 0.49836066 | Z8: 0.48407643 | AA8: 0.4911147 | AB8: 314 | AC8: 0.56914894 | AD8: 0.58310627 | AE8: 0.57604307 | AF8: 367 | AG8: 0.067345948 | AH8: 152 | AI8: 162 | AJ8: 153 | AK8: 214 | AL8: 0.51787171 | AM8: 0.54064128 | AN8: 1000 | AO8: 0.49769534 | AP8: 0.57676091 | AQ8: 0.49610615 | AR8: 0.573106 | AS8: 0.49488255 | AT8: 0.57280974 | AU8: -0.0078090292 | AV8: 0.14685705 | AW8: 0.46730011 | AX8: 0.56528353 | AY8: 0.48689105 | AZ8: 0.59979455
A9: emognition_features_w60_o30__valence__windowed__nvg__xgboost | B9: emognition_features_w60_o30 | C9: 60 | D9: 30 | E9: valence | F9: windowed | G9: nvg | H9: xgboost | I9: 48 | J9: 48 | K9: 42 | L9: 42 | M9: TRUE | N9: FALSE | O9: 652.18539 | P9: 681 | Q9: 314 | R9: 367 | S9: TRUE | T9: 0.54185022 | U9: 0.53836842 | V9: 0.53848665 | W9: 0.53836842 | X9: 0.53838533 | Y9: 0.50324675 | Z9: 0.49363057 | AA9: 0.49839228 | AB9: 314 | AC9: 0.57372654 | AD9: 0.58310627 | AE9: 0.57837838 | AF9: 367 | AG9: 0.076854977 | AH9: 155 | AI9: 159 | AJ9: 153 | AK9: 214 | AL9: 0.55274302 | AM9: 0.55967942 | AN9: 1000 | AO9: 0.50374026 | AP9: 0.57865696 | AQ9: 0.5019786 | AR9: 0.57645674 | AS9: 0.50019489 | AT9: 0.57554109 | AU9: 0.0039704471 | AV9: 0.15269457 | AW9: 0.49964336 | AX9: 0.6066552 | AY9: 0.49267039 | AZ9: 0.6396292
A10: emognition_features_w60_o30__valence__windowed__hvg__svm | B10: emognition_features_w60_o30 | C10: 60 | D10: 30 | E10: valence | F10: windowed | G10: hvg | H10: svm | I10: 48 | J10: 48 | K10: 42 | L10: 42 | M10: TRUE | N10: FALSE | O10: 41.298882 | P10: 681 | Q10: 314 | R10: 367 | S10: TRUE | T10: 0.49339207 | U10: 0.48651053 | V10: 0.48616993 | W10: 0.48651053 | X10: 0.48518182 | Y10: 0.44483986 | Z10: 0.39808917 | AA10: 0.42016807 | AB10: 314 | AC10: 0.5275 | AD10: 0.57493188 | AE10: 0.55019557 | AF10: 367 | AG10: -0.027317422 | AH10: 125 | AI10: 189 | AJ10: 156 | AK10: 211 | AL10: 0.47394089 | AM10: 0.51159706 | AN10: 1000 | AO10: 0.45146167 | AP10: 0.53870203 | AQ10: 0.4469765 | AR10: 0.5329878 | AS10: 0.44221527 | AT10: 0.53099986 | AU10: -0.10838235 | AV10: 0.066973531 | AW10: 0.42040867 | AX10: 0.52535284 | AY10: 0.45607618 | AZ10: 0.57324991
A11: emognition_features_w60_o30__valence__windowed__hvg__rf | B11: emognition_features_w60_o30 | C11: 60 | D11: 30 | E11: valence | F11: windowed | G11: hvg | H11: rf | I11: 48 | J11: 48 | K11: 42 | L11: 42 | M11: TRUE | N11: FALSE | O11: 489.34618 | P11: 681 | Q11: 314 | R11: 367 | S11: TRUE | T11: 0.51835536 | U11: 0.51105104 | V11: 0.51139291 | W11: 0.51105104 | X11: 0.50959867 | Y11: 0.47463768 | Z11: 0.41719745 | AA11: 0.4440678 | AB11: 314 | AC11: 0.54814815 | AD11: 0.60490463 | AE11: 0.57512953 | AF11: 367 | AG11: 0.022441353 | AH11: 131 | AI11: 183 | AJ11: 145 | AK11: 222 | AL11: 0.50169649 | AM11: 0.54677056 | AN11: 1000 | AO11: 0.48036221 | AP11: 0.55325615 | AQ11: 0.47537765 | AR11: 0.54516285 | AS11: 0.47275372 | AT11: 0.54326458 | AU11: -0.050293479 | AV11: 0.092310756 | AW11: 0.45994186 | AX11: 0.54369198 | AY11: 0.49393189 | AZ11: 0.60057957
A12: emognition_features_w60_o30__valence__windowed__hvg__knn | B12: emognition_features_w60_o30 | C12: 60 | D12: 30 | E12: valence | F12: windowed | G12: hvg | H12: knn | I12: 48 | J12: 48 | K12: 42 | L12: 42 | M12: TRUE | N12: FALSE | O12: 23.983551 | P12: 681 | Q12: 314 | R12: 367 | S12: TRUE | T12: 0.46549192 | U12: 0.46131484 | V12: 0.46115033 | W12: 0.46131484 | X12: 0.46116859 | Y12: 0.41830065 | Z12: 0.40764331 | AA12: 0.41290323 | AB12: 314 | AC12: 0.504 | AD12: 0.51498638 | AE12: 0.50943396 | AF12: 367 | AG12: -0.077534655 | AH12: 128 | AI12: 186 | AJ12: 178 | AK12: 189 | AL12: 0.46212621 | AM12: 0.5187852 | AN12: 1000 | AO12: 0.41947869 | AP12: 0.5079648 | AQ12: 0.41570525 | AR12: 0.50416315 | AS12: 0.41571507 | AT12: 0.50274471 | AU12: -0.16840157 | AV12: 0.0082702503 | AW12: 0.41931863 | AX12: 0.50872109 | AY12: 0.47595216 | AZ12: 0.55985259
A13: emognition_features_w60_o30__valence__windowed__hvg__xgboost | B13: emognition_features_w60_o30 | C13: 60 | D13: 30 | E13: valence | F13: windowed | G13: hvg | H13: xgboost | I13: 48 | J13: 48 | K13: 42 | L13: 42 | M13: TRUE | N13: FALSE | O13: 586.78494 | P13: 681 | Q13: 314 | R13: 367 | S13: TRUE | T13: 0.51248164 | U13: 0.50882088 | V13: 0.50884806 | W13: 0.50882088 | X13: 0.50879465 | Y13: 0.47077922 | Z13: 0.46178344 | AA13: 0.46623794 | AB13: 314 | AC13: 0.54691689 | AD13: 0.55585831 | AE13: 0.55135135 | AF13: 367 | AG13: 0.01766891 | AH13: 145 | AI13: 169 | AJ13: 163 | AK13: 204 | AL13: 0.51940332 | AM13: 0.57317044 | AN13: 1000 | AO13: 0.47685039 | AP13: 0.54977046 | AQ13: 0.47409393 | AR13: 0.54493665 | AS13: 0.47392687 | AT13: 0.54476814 | AU13: -0.05202887 | AV13: 0.090449205 | AW13: 0.47587489 | AX13: 0.56287191 | AY13: 0.51360799 | AZ13: 0.63195879
... A81: emognition_features_w60_o30__arousal__aggregated__hc+hvg__xgboost | B81: emognition_features_w60_o30 | C81: 60 | D81: 30 | E81: arousal | F81: aggregated | G81: hc+hvg | H81: xgboost | I81: 77 | J81: 154 | K81: 42 | L81: 42 | M81: TRUE | N81: FALSE | O81: 1056.56 | P81: 278 | Q81: 151 | R81: 127 | S81: TRUE | T81: 0.47122302 | U81: 0.46568806 | V81: 0.46542665 | W81: 0.46568806 | X81: 0.4654056 | Y81: 0.51282051 | Z81: 0.52980132 | AA81: 0.52117264 | AB81: 151 | AC81: 0.41803279 | AD81: 0.4015748 | AE81: 0.40963855 | AF81: 127 | AG81: -0.06888479 | AH81: 80 | AI81: 71 | AJ81: 76 | AK81: 51 | AL81: 0.48120144 | AM81: 0.43365572 | AN81: 1000 | AO81: 0.38297872 | AP81: 0.55518039 | AQ81: 0.38331973 | AR81: 0.54880801 | AS81: 0.37941117 | AT81: 0.54275775 | AU81: -0.23614575 | AV81: 0.097696705 | AW81: 0.37667471 | AX81: 0.58733607 | AY81: 0.31397698 | AZ81: 0.59857411
A82: emognition_features_w60_o30__valence__windowed__hc__mlp | B82: emognition_features_w60_o30 | C82: 60 | D82: 30 | E82: valence | F82: windowed | G82: hc | H82: mlp | I82: 29 | J82: 29 | K82: 42 | L82: 42 | M82: TRUE | N82: FALSE | O82: 620.51997 | P82: 681 | Q82: 314 | R82: 367 | S82: TRUE | T82: 0.47723935 | U82: 0.47727312 | V82: 0.47741034 | W82: 0.47727312 | X82: 0.47653389 | Y82: 0.43859649 | Z82: 0.47770701 | AA82: 0.45731707 | AB82: 314 | AC82: 0.51622419 | AD82: 0.47683924 | AE82: 0.49575071 | AF82: 367 | AG82: -0.045316331 | AH82: 150 | AI82: 164 | AJ82: 192 | AK82: 175 | AL82: 0.48317395 | AM82: 0.53389472 | AN82: 0 | AO82: NaN | AP82: NaN | AQ82: NaN | AR82: NaN | AS82: NaN | AT82: NaN | AU82: NaN | AV82: NaN | AW82: NaN | AX82: NaN | AY82: NaN | AZ82: NaN
A83: emognition_features_w60_o30__valence__windowed__nvg__mlp | B83: emognition_features_w60_o30 | C83: 60 | D83: 30 | E83: valence | F83: windowed | G83: nvg | H83: mlp | I83: 48 | J83: 48 | K83: 42 | L83: 42 | M83: TRUE | N83: FALSE | O83: 563.66697 | P83: 681 | Q83: 314 | R83: 367 | S83: TRUE | T83: 0.53303965 | U83: 0.53134383 | V83: 0.53122731 | W83: 0.53134383 | X83: 0.53117044 | Y83: 0.49382716 | Z83: 0.50955414 | AA83: 0.5015674 | AB83: 314 | AC83: 0.56862745 | AD83: 0.55313351 | AE83: 0.56077348 | AF83: 367 | AG83: 0.062571025 | AH83: 160 | AI83: 154 | AJ83: 164 | AK83: 203 | AL83: 0.54437772 | AM83: 0.56090018 | AN83: 0 | AO83: NaN | AP83: NaN | AQ83: NaN | AR83: NaN | AS83: NaN | AT83: NaN | AU83: NaN | AV83: NaN | AW83: NaN | AX83: NaN | AY83: NaN | AZ83: NaN
A84: emognition_features_w60_o30__valence__windowed__hvg__mlp | B84: emognition_features_w60_o30 | C84: 60 | D84: 30 | E84: valence | F84: windowed | G84: hvg | H84: mlp | I84: 48 | J84: 48 | K84: 42 | L84: 42 | M84: TRUE | N84: FALSE | O84: 529.32567 | P84: 681 | Q84: 314 | R84: 367 | S84: TRUE | T84: 0.52129222 | U84: 0.52021469 | V84: 0.52011137 | W84: 0.52021469 | X84: 0.51987491 | Y84: 0.48181818 | Z84: 0.50636943 | AA84: 0.49378882 | AB84: 314 | AC84: 0.55840456 | AD84: 0.53405995 | AE84: 0.545961 | AF84: 367 | AG84: 0.040325924 | AH84: 159 | AI84: 155 | AJ84: 171 | AK84: 196 | AL84: 0.50891199 | AM84: 0.54344937 | AN84: 0 | AO84: NaN | AP84: NaN | AQ84: NaN | AR84: NaN | AS84: NaN | AT84: NaN | AU84: NaN | AV84: NaN | AW84: NaN | AX84: NaN | AY84: NaN | AZ84: NaN
A85: emognition_features_w60_o30__valence__windowed__hc+nvg__mlp | B85: emognition_features_w60_o30 | C85: 60 | D85: 30 | E85: valence | F85: windowed | G85: hc+nvg | H85: mlp | I85: 77 | J85: 77 | K85: 42 | L85: 42 | M85: TRUE | N85: FALSE | O85: 583.86257 | P85: 681 | Q85: 314 | R85: 367 | S85: TRUE | T85: 0.51835536 | U85: 0.5163401 | V85: 0.51628921 | W85: 0.5163401 | X85: 0.51624305 | Y85: 0.47826087 | Z85: 0.49044586 | AA85: 0.48427673 | AB85: 314 | AC85: 0.55431755 | AD85: 0.54223433 | AE85: 0.54820937 | AF85: 367 | AG85: 0.032629266 | AH85: 154 | AI85: 160 | AJ85: 168 | AK85: 199 | AL85: 0.50685538 | AM85: 0.54377009 | AN85: 0 | AO85: NaN | AP85: NaN | AQ85: NaN | AR85: NaN | AS85: NaN | AT85: NaN | AU85: NaN | AV85: NaN | AW85: NaN | AX85: NaN | AY85: NaN | AZ85: NaN
A86: emognition_features_w60_o30__valence__windowed__hc+hvg__mlp | B86: emognition_features_w60_o30 | C86: 60 | D86: 30 | E86: valence | F86: windowed | G86: hc+hvg | H86: mlp | I86: 77 | J86: 77 | K86: 42 | L86: 42 | M86: TRUE | N86: FALSE | O86: 563.08585 | P86: 681 | Q86: 314 | R86: 367 | S86: TRUE | T86: 0.49192364 | U86: 0.49043718 | V86: 0.49048228 | W86: 0.49043718 | X86: 0.49025182 | Y86: 0.45121951 | Z86: 0.47133758 | AA86: 0.46105919 | AB86: 314 | AC86: 0.52974504 | AD86: 0.50953678 | AE86: 0.51944444 | AF86: 367 | AG86: -0.019080487 | AH86: 148 | AI86: 166 | AJ86: 180 | AK86: 187 | AL86: 0.46513303 | AM86: 0.5188941 | AN86: 0 | AO86: NaN | AP86: NaN | AQ86: NaN | AR86: NaN | AS86: NaN | AT86: NaN | AU86: NaN | AV86: NaN | AW86: NaN | AX86: NaN | AY86: NaN | AZ86: NaN
A87: emognition_features_w60_o30__valence__aggregated__hc__mlp | B87: emognition_features_w60_o30 | C87: 60 | D87: 30 | E87: valence | F87: aggregated | G87: hc | H87: mlp | I87: 29 | J87: 58 | K87: 42 | L87: 42 | M87: TRUE | N87: FALSE | O87: 266.60992 | P87: 304 | Q87: 140 | R87: 164 | S87: TRUE | T87: 0.52960526 | U87: 0.53318815 | V87: 0.53322433 | W87: 0.53318815 | X87: 0.52960017 | Y87: 0.49090909 | Z87: 0.57857143 | AA87: 0.53114754 | AB87: 140 | AC87: 0.57553957 | AD87: 0.48780488 | AE87: 0.52805281 | AF87: 164 | AG87: 0.066412473 | AH87: 81 | AI87: 59 | AJ87: 84 | AK87: 80 | AL87: 0.53706446 | AM87: 0.57692219 | AN87: 0 | AO87: NaN | AP87: NaN | AQ87: NaN | AR87: NaN | AS87: NaN | AT87: NaN | AU87: NaN | AV87: NaN | AW87: NaN | AX87: NaN | AY87: NaN | AZ87: NaN
A88: emognition_features_w60_o30__valence__aggregated__nvg__mlp | B88: emognition_features_w60_o30 | C88: 60 | D88: 30 | E88: valence | F88: aggregated | G88: nvg | H88: mlp | I88: 48 | J88: 96 | K88: 42 | L88: 42 | M88: TRUE | N88: FALSE | O88: 291.86344 | P88: 304 | Q88: 140 | R88: 164 | S88: TRUE | T88: 0.54276316 | U88: 0.54381533 | V88: 0.54355921 | W88: 0.54381533 | X88: 0.54236205 | Y88: 0.50322581 | Z88: 0.55714286 | AA88: 0.52881356 | AB88: 140 | AC88: 0.58389262 | AD88: 0.5304878 | AE88: 0.55591054 | AF88: 164 | AG88: 0.087374168 | AH88: 78 | AI88: 62 | AJ88: 77 | AK88: 87 | AL88: 0.55426829 | AM88: 0.58136677 | AN88: 0 | AO88: NaN | AP88: NaN | AQ88: NaN | AR88: NaN | AS88: NaN | AT88: NaN | AU88: NaN | AV88: NaN | AW88: NaN | AX88: NaN | AY88: NaN | AZ88: NaN
A89: emognition_features_w60_o30__valence__aggregated__hvg__mlp | B89: emognition_features_w60_o30 | C89: 60 | D89: 30 | E89: valence | F89: aggregated | G89: hvg | H89: mlp | I89: 48 | J89: 96 | K89: 42 | L89: 42 | M89: TRUE | N89: FALSE | O89: 279.47167 | P89: 304 | Q89: 140 | R89: 164 | S89: TRUE | T89: 0.4375 | U89: 0.43998258 | V89: 0.44004264 | W89: 0.43998258 | X89: 0.43749391 | Y89: 0.40490798 | Z89: 0.47142857 | AA89: 0.43564356 | AB89: 140 | AC89: 0.4751773 | AD89: 0.40853659 | AE89: 0.43934426 | AF89: 164 | AG89: -0.11997477 | AH89: 66 | AI89: 74 | AJ89: 97 | AK89: 67 | AL89: 0.44407666 | AM89: 0.50576348 | AN89: 0 | AO89: NaN | AP89: NaN | AQ89: NaN | AR89: NaN | AS89: NaN | AT89: NaN | AU89: NaN | AV89: NaN | AW89: NaN | AX89: NaN | AY89: NaN | AZ89: NaN
A90: emognition_features_w60_o30__valence__aggregated__hc+nvg__mlp | B90: emognition_features_w60_o30 | C90: 60 | D90: 30 | E90: valence | F90: aggregated | G90: hc+nvg | H90: mlp | I90: 77 | J90: 154 | K90: 42 | L90: 42 | M90: TRUE | N90: FALSE | O90: 308.92189 | P90: 304 | Q90: 140 | R90: 164 | S90: TRUE | T90: 0.55921053 | U90: 0.56271777 | V90: 0.56271777 | W90: 0.56271777 | X90: 0.55921053 | Y90: 0.51829268 | Z90: 0.60714286 | AA90: 0.55921053 | AB90: 140 | AC90: 0.60714286 | AD90: 0.51829268 | AE90: 0.55921053 | AF90: 164 | AG90: 0.12543554 | AH90: 85 | AI90: 55 | AJ90: 79 | AK90: 85 | AL90: 0.54586237 | AM90: 0.57687446 | AN90: 0 | AO90: NaN | AP90: NaN | AQ90: NaN | AR90: NaN | AS90: NaN | AT90: NaN | AU90: NaN | AV90: NaN | AW90: NaN | AX90: NaN | AY90: NaN | AZ90: NaN
A91: emognition_features_w60_o30__valence__aggregated__hc+hvg__mlp | B91: emognition_features_w60_o30 | C91: 60 | D91: 30 | E91: valence | F91: aggregated | G91: hc+hvg | H91: mlp | I91: 77 | J91: 154 | K91: 42 | L91: 42 | M91: TRUE | N91: FALSE | O91: 297.71865 | P91: 304 | Q91: 140 | R91: 164 | S91: TRUE | T91: 0.52960526 | U91: 0.53057491 | V91: 0.53039619 | W91: 0.53057491 | X91: 0.52919261 | Y91: 0.49032258 | Z91: 0.54285714 | AA91: 0.51525424 | AB91: 140 | AC91: 0.5704698 | AD91: 0.51829268 | AE91: 0.54313099 | AF91: 164 | AG91: 0.060970841 | AH91: 76 | AI91: 64 | AJ91: 79 | AK91: 85 | AL91: 0.51986063 | AM91: 0.5547337 | AN91: 0 | AO91: NaN | AP91: NaN | AQ91: NaN | AR91: NaN | AS91: NaN | AT91: NaN | AU91: NaN | AV91: NaN | AW91: NaN | AX91: NaN | AY91: NaN | AZ91: NaN
A92: emognition_features_w60_o30__arousal__windowed__hc__mlp | B92: emognition_features_w60_o30 | C92: 60 | D92: 30 | E92: arousal | F92: windowed | G92: hc | H92: mlp | I92: 29 | J92: 29 | K92: 42 | L92: 42 | M92: TRUE | N92: FALSE | O92: 632.75676 | P92: 624 | Q92: 333 | R92: 291 | S92: TRUE | T92: 0.46474359 | U92: 0.4629578 | V92: 0.46304019 | W92: 0.4629578 | X92: 0.46295609 | Y92: 0.49847095 | Z92: 0.48948949 | AA92: 0.49393939 | AB92: 333 | AC92: 0.42760943 | AD92: 0.43642612 | AE92: 0.43197279 | AF92: 291 | AG92: -0.074001963 | AH92: 163 | AI92: 170 | AJ92: 164 | AK92: 127 | AL92: 0.45897444 | AM92: 0.43255643 | AN92: 0 | AO92: NaN | AP92: NaN | AQ92: NaN | AR92: NaN | AS92: NaN | AT92: NaN | AU92: NaN | AV92: NaN | AW92: NaN | AX92: NaN | AY92: NaN | AZ92: NaN
A93: emognition_features_w60_o30__arousal__windowed__nvg__mlp | B93: emognition_features_w60_o30 | C93: 60 | D93: 30 | E93: arousal | F93: windowed | G93: nvg | H93: mlp | I93: 48 | J93: 48 | K93: 42 | L93: 42 | M93: TRUE | N93: FALSE | O93: 566.68425 | P93: 624 | Q93: 333 | R93: 291 | S93: TRUE | T93: 0.54326923 | U93: 0.5425993 | V93: 0.54243421 | W93: 0.5425993 | X93: 0.54228062 | Y93: 0.575 | Z93: 0.55255255 | AA93: 0.56355283 | AB93: 333 | AC93: 0.50986842 | AD93: 0.53264605 | AE93: 0.5210084 | AF93: 291 | AG93: 0.085033351 | AH93: 184 | AI93: 149 | AJ93: 136 | AK93: 155 | AL93: 0.5641105 | AM93: 0.53825941 | AN93: 0 | AO93: NaN | AP93: NaN | AQ93: NaN | AR93: NaN | AS93: NaN | AT93: NaN | AU93: NaN | AV93: NaN | AW93: NaN | AX93: NaN | AY93: NaN | AZ93: NaN
... A101: emognition_features_w60_o30__arousal__aggregated__hc+hvg__mlp | B101: emognition_features_w60_o30 | C101: 60 | D101: 30 | E101: arousal | F101: aggregated | G101: hc+hvg | H101: mlp | I101: 77 | J101: 154 | K101: 42 | L101: 42 | M101: TRUE | N101: FALSE | O101: 335.06938 | P101: 278 | Q101: 151 | R101: 127 | S101: TRUE | T101: 0.48201439 | U101: 0.48688533 | V101: 0.48680829 | W101: 0.48688533 | X101: 0.48190713 | Y101: 0.52845528 | Z101: 0.43046358 | AA101: 0.47445255 | AB101: 151 | AC101: 0.44516129 | AD101: 0.54330709 | AE101: 0.4893617 | AF101: 127 | AG101: -0.026306268 | AH101: 65 | AI101: 86 | AJ101: 58 | AK101: 69 | AL101: 0.49611514 | AM101: 0.45127758 | AN101: 0 | AO101: NaN | AP101: NaN | AQ101: NaN | AR101: NaN | AS101: NaN | AT101: NaN | AU101: NaN | AV101: NaN | AW101: NaN | AX101: NaN | AY101: NaN | AZ101: NaN
A102: experiment_id | B102: input_id | C102: window_sec | D102: overlap_sec | E102: target | F102: input_mode | G102: representation | H102: model | I102: feature_count_before_aggregation | J102: input_feature_count | K102: subjects_total | L102: outer_folds_run | M102: complete_loso | N102: quick_grid | O102: experiment_seconds | P102: n_samples | Q102: n_low | R102: n_high | S102: fold_has_both_classes | T102: accuracy | U102: balanced_accuracy_fixed | V102: macro_precision_fixed | W102: macro_recall_fixed | X102: macro_f1_fixed | Y102: low_precision | Z102: low_recall | AA102: low_f1 | AB102: low_support | AC102: high_precision | AD102: high_recall | AE102: high_f1 | AF102: high_support | AG102: mcc | AH102: tn | AI102: fp | AJ102: fn | AK102: tp | AL102: roc_auc | AM102: average_precision | AN102: bootstrap_repeats | AO102: accuracy_ci_low | AP102: accuracy_ci_high | AQ102: balanced_accuracy_fixed_ci_low | AR102: balanced_accuracy_fixed_ci_high | AS102: macro_f1_fixed_ci_low | AT102: macro_f1_fixed_ci_high | AU102: mcc_ci_low | AV102: mcc_ci_high | AW102: roc_auc_ci_low | AX102: roc_auc_ci_high | AY102: average_precision_ci_low | AZ102: average_precision_ci_high
A103: emognition_features_w60_o30__valence__windowed__nvg__gcn | B103: emognition_features_w60_o30 | C103: 60 | D103: 30 | E103: valence | F103: windowed | G103: nvg | H103: gcn | I103: 48 | J103: 48 | K103: 42 | L103: 42 | M103: TRUE | N103: TRUE | O103: 631.22987 | P103: 681 | Q103: 314 | R103: 367 | S103: TRUE | T103: 0.55212922 | U103: 0.549055 | V103: 0.54912662 | W103: 0.549055 | X103: 0.54908005 | Y103: 0.51446945 | Z103: 0.50955414 | AA103: 0.512 | AB103: 314 | AC103: 0.58378378 | AD103: 0.58855586 | AE103: 0.58616011 | AF103: 367 | AG103: 0.098181592 | AH103: 160 | AI103: 154 | AJ103: 151 | AK103: 216 | AL103: 0.55369757 | AM103: 0.56151019 | AN103: 0 | AO103: NaN | AP103: NaN | AQ103: NaN | AR103: NaN | AS103: NaN | AT103: NaN | AU103: NaN | AV103: NaN | AW103: NaN | AX103: NaN | AY103: NaN | AZ103: NaN
A104: emognition_features_w60_o30__valence__aggregated__nvg__gat | B104: emognition_features_w60_o30 | C104: 60 | D104: 30 | E104: valence | F104: aggregated | G104: nvg | H104: gat | I104: 48 | J104: 96 | K104: 42 | L104: 42 | M104: TRUE | N104: TRUE | O104: 330.69621 | P104: 304 | Q104: 140 | R104: 164 | S104: TRUE | T104: 0.53947368 | U104: 0.53606272 | V104: 0.53614458 | W104: 0.53606272 | X104: 0.53608023 | Y104: 0.5 | Z104: 0.49285714 | AA104: 0.49640288 | AB104: 140 | AC104: 0.57228916 | AD104: 0.57926829 | AE104: 0.57575758 | AF104: 164 | AG104: 0.07220725 | AH104: 69 | AI104: 71 | AJ104: 69 | AK104: 95 | AL104: 0.51271777 | AM104: 0.54678821 | AN104: 0 | AO104: NaN | AP104: NaN | AQ104: NaN | AR104: NaN | AS104: NaN | AT104: NaN | AU104: NaN | AV104: NaN | AW104: NaN | AX104: NaN | AY104: NaN | AZ104: NaN
A105: emognition_features_w60_o30__valence__windowed__nvg__gat | B105: emognition_features_w60_o30 | C105: 60 | D105: 30 | E105: valence | F105: windowed | G105: nvg | H105: gat | I105: 48 | J105: 48 | K105: 42 | L105: 42 | M105: TRUE | N105: TRUE | O105: 726.10257 | P105: 681 | Q105: 314 | R105: 367 | S105: TRUE | T105: 0.53597651 | U105: 0.53360871 | V105: 0.53355164 | W105: 0.53360871 | X105: 0.53356164 | Y105: 0.49685535 | Z105: 0.50318471 | AA105: 0.5 | AB105: 314 | AC105: 0.57024793 | AD105: 0.5640327 | AE105: 0.56712329 | AF105: 367 | AG105: 0.067160321 | AH105: 158 | AI105: 156 | AJ105: 160 | AK105: 207 | AL105: 0.53813846 | AM105: 0.57270694 | AN105: 0 | AO105: NaN | AP105: NaN | AQ105: NaN | AR105: NaN | AS105: NaN | AT105: NaN | AU105: NaN | AV105: NaN | AW105: NaN | AX105: NaN | AY105: NaN | AZ105: NaN
A106: emognition_features_w60_o30__valence__aggregated__hvg__gcn | B106: emognition_features_w60_o30 | C106: 60 | D106: 30 | E106: valence | F106: aggregated | G106: hvg | H106: gcn | I106: 48 | J106: 96 | K106: 42 | L106: 42 | M106: TRUE | N106: TRUE | O106: 261.39236 | P106: 304 | Q106: 140 | R106: 164 | S106: TRUE | T106: 0.53289474 | U106: 0.53414634 | V106: 0.53395703 | W106: 0.53414634 | X106: 0.53257103 | Y106: 0.49358974 | Z106: 0.55 | AA106: 0.52027027 | AB106: 140 | AC106: 0.57432432 | AD106: 0.51829268 | AE106: 0.54487179 | AF106: 164 | AG106: 0.068103112 | AH106: 77 | AI106: 63 | AJ106: 79 | AK106: 85 | AL106: 0.52682927 | AM106: 0.56020284 | AN106: 0 | AO106: NaN | AP106: NaN | AQ106: NaN | AR106: NaN | AS106: NaN | AT106: NaN | AU106: NaN | AV106: NaN | AW106: NaN | AX106: NaN | AY106: NaN | AZ106: NaN
A107: emognition_features_w60_o30__arousal__windowed__hvg__gcn | B107: emognition_features_w60_o30 | C107: 60 | D107: 30 | E107: arousal | F107: windowed | G107: hvg | H107: gcn | I107: 48 | J107: 48 | K107: 42 | L107: 42 | M107: TRUE | N107: TRUE | O107: 490.47148 | P107: 624 | Q107: 333 | R107: 291 | S107: TRUE | T107: 0.52724359 | U107: 0.52585059 | V107: 0.5257854 | W107: 0.52585059 | X107: 0.52575158 | Y107: 0.55828221 | Z107: 0.54654655 | AA107: 0.55235205 | AB107: 333 | AC107: 0.49328859 | AD107: 0.50515464 | AE107: 0.4991511 | AF107: 291 | AG107: 0.051635951 | AH107: 182 | AI107: 151 | AJ107: 144 | AK107: 147 | AL107: 0.52253284 | AM107: 0.49778788 | AN107: 0 | AO107: NaN | AP107: NaN | AQ107: NaN | AR107: NaN | AS107: NaN | AT107: NaN | AU107: NaN | AV107: NaN | AW107: NaN | AX107: NaN | AY107: NaN | AZ107: NaN
A108: emognition_features_w60_o30__arousal__windowed__nvg__gat | B108: emognition_features_w60_o30 | C108: 60 | D108: 30 | E108: arousal | F108: windowed | G108: nvg | H108: gat | I108: 48 | J108: 48 | K108: 42 | L108: 42 | M108: TRUE | N108: TRUE | O108: 625.09642 | P108: 624 | Q108: 333 | R108: 291 | S108: TRUE | T108: 0.5224359 | U108: 0.52264636 | V108: 0.52254399 | W108: 0.52264636 | X108: 0.5219448 | Y108: 0.5562701 | Z108: 0.51951952 | AA108: 0.53726708 | AB108: 333 | AC108: 0.48881789 | AD108: 0.5257732 | AE108: 0.50662252 | AF108: 291 | AG108: 0.045190236 | AH108: 173 | AI108: 160 | AJ108: 138 | AK108: 153 | AL108: 0.50116095 | AM108: 0.48029025 | AN108: 0 | AO108: NaN | AP108: NaN | AQ108: NaN | AR108: NaN | AS108: NaN | AT108: NaN | AU108: NaN | AV108: NaN | AW108: NaN | AX108: NaN | AY108: NaN | AZ108: NaN
A109: emognition_features_w60_o30__arousal__windowed__hvg__gat | B109: emognition_features_w60_o30 | C109: 60 | D109: 30 | E109: arousal | F109: windowed | G109: hvg | H109: gat | I109: 48 | J109: 48 | K109: 42 | L109: 42 | M109: TRUE | N109: TRUE | O109: 611.47299 | P109: 624 | Q109: 333 | R109: 291 | S109: TRUE | T109: 0.51602564 | U109: 0.51468995 | V109: 0.51464883 | W109: 0.51468995 | X109: 0.51458451 | Y109: 0.54769231 | Z109: 0.53453453 | AA109: 0.54103343 | AB109: 333 | AC109: 0.48160535 | AD109: 0.49484536 | AE109: 0.48813559 | AF109: 291 | AG109: 0.029338748 | AH109: 178 | AI109: 155 | AJ109: 147 | AK109: 144 | AL109: 0.54774362 | AM109: 0.48308361 | AN109: 0 | AO109: NaN | AP109: NaN | AQ109: NaN | AR109: NaN | AS109: NaN | AT109: NaN | AU109: NaN | AV109: NaN | AW109: NaN | AX109: NaN | AY109: NaN | AZ109: NaN
A110: emognition_features_w60_o30__valence__aggregated__nvg__gcn | B110: emognition_features_w60_o30 | C110: 60 | D110: 30 | E110: valence | F110: aggregated | G110: nvg | H110: gcn | I110: 48 | J110: 96 | K110: 42 | L110: 42 | M110: TRUE | N110: TRUE | O110: 283.67283 | P110: 304 | Q110: 140 | R110: 164 | S110: TRUE | T110: 0.51315789 | U110: 0.51689895 | V110: 0.51693731 | W110: 0.51689895 | X110: 0.51313682 | Y110: 0.47590361 | Z110: 0.56428571 | AA110: 0.51633987 | AB110: 140 | AC110: 0.55797101 | AD110: 0.4695122 | AE110: 0.50993377 | AF110: 164 | AG110: 0.033836247 | AH110: 79 | AI110: 61 | AJ110: 87 | AK110: 77 | AL110: 0.49834495 | AM110: 0.55622024 | AN110: 0 | AO110: NaN | AP110: NaN | AQ110: NaN | AR110: NaN | AS110: NaN | AT110: NaN | AU110: NaN | AV110: NaN | AW110: NaN | AX110: NaN | AY110: NaN | AZ110: NaN
A111: emognition_features_w60_o30__arousal__aggregated__hvg__gat | B111: emognition_features_w60_o30 | C111: 60 | D111: 30 | E111: arousal | F111: aggregated | G111: hvg | H111: gat | I111: 48 | J111: 96 | K111: 42 | L111: 42 | M111: TRUE | N111: TRUE | O111: 272.60378 | P111: 278 | Q111: 151 | R111: 127 | S111: TRUE | T111: 0.48920863 | U111: 0.48036711 | V111: 0.47968927 | W111: 0.48036711 | X111: 0.47841023 | Y111: 0.52694611 | Z111: 0.58278146 | AA111: 0.55345912 | AB111: 151 | AC111: 0.43243243 | AD111: 0.37795276 | AE111: 0.40336134 | AF111: 127 | AG111: -0.039937872 | AH111: 88 | AI111: 63 | AJ111: 79 | AK111: 48 | AL111: 0.4512176 | AM111: 0.41659888 | AN111: 0 | AO111: NaN | AP111: NaN | AQ111: NaN | AR111: NaN | AS111: NaN | AT111: NaN | AU111: NaN | AV111: NaN | AW111: NaN | AX111: NaN | AY111: NaN | AZ111: NaN
A112: emognition_features_w60_o30__arousal__aggregated__nvg__gat | B112: emognition_features_w60_o30 | C112: 60 | D112: 30 | E112: arousal | F112: aggregated | G112: nvg | H112: gat | I112: 48 | J112: 96 | K112: 42 | L112: 42 | M112: TRUE | N112: TRUE | O112: 275.54087 | P112: 278 | Q112: 151 | R112: 127 | S112: TRUE | T112: 0.48561151 | U112: 0.48331334 | V112: 0.4833956 | W112: 0.48331334 | X112: 0.48319748 | Y112: 0.52739726 | Z112: 0.50993377 | AA112: 0.51851852 | AB112: 151 | AC112: 0.43939394 | AD112: 0.45669291 | AE112: 0.44787645 | AF112: 127 | AG112: -0.033290954 | AH112: 77 | AI112: 74 | AJ112: 69 | AK112: 58 | AL112: 0.46018668 | AM112: 0.44746949 | AN112: 0 | AO112: NaN | AP112: NaN | AQ112: NaN | AR112: NaN | AS112: NaN | AT112: NaN | AU112: NaN | AV112: NaN | AW112: NaN | AX112: NaN | AY112: NaN | AZ112: NaN
A113: emognition_features_w60_o30__arousal__windowed__nvg__gcn | B113: emognition_features_w60_o30 | C113: 60 | D113: 30 | E113: arousal | F113: windowed | G113: nvg | H113: gcn | I113: 48 | J113: 48 | K113: 42 | L113: 42 | M113: TRUE | N113: TRUE | O113: 489.52864 | P113: 624 | Q113: 333 | R113: 291 | S113: TRUE | T113: 0.48237179 | U113: 0.4809913 | V113: 0.48104938 | W113: 0.4809913 | X113: 0.48092004 | Y113: 0.5154321 | Z113: 0.5015015 | AA113: 0.50837139 | AB113: 333 | AC113: 0.44666667 | AD113: 0.4604811 | AE113: 0.4534687 | AF113: 291 | AG113: -0.037959272 | AH113: 167 | AI113: 166 | AJ113: 157 | AK113: 134 | AL113: 0.47859199 | AM113: 0.44249439 | AN113: 0 | AO113: NaN | AP113: NaN | AQ113: NaN | AR113: NaN | AS113: NaN | AT113: NaN | AU113: NaN | AV113: NaN | AW113: NaN | AX113: NaN | AY113: NaN | AZ113: NaN
A114: emognition_features_w60_o30__valence__windowed__hvg__gat | B114: emognition_features_w60_o30 | C114: 60 | D114: 30 | E114: valence | F114: windowed | G114: hvg | H114: gat | I114: 48 | J114: 48 | K114: 42 | L114: 42 | M114: TRUE | N114: TRUE | O114: 717.46457 | P114: 681 | Q114: 314 | R114: 367 | S114: TRUE | T114: 0.48164464 | U114: 0.47607126 | V114: 0.47574417 | W114: 0.47607126 | X114: 0.47545087 | Y114: 0.4334471 | Z114: 0.4044586 | AA114: 0.4184514 | AB114: 314 | AC114: 0.51804124 | AD114: 0.54768392 | AE114: 0.53245033 | AF114: 367 | AG114: -0.048183461 | AH114: 127 | AI114: 187 | AJ114: 166 | AK114: 201 | AL114: 0.47876568 | AM114: 0.52744303 | AN114: 0 | AO114: NaN | AP114: NaN | AQ114: NaN | AR114: NaN | AS114: NaN | AT114: NaN | AU114: NaN | AV114: NaN | AW114: NaN | AX114: NaN | AY114: NaN | AZ114: NaN
...

Sheet Results
BZ1: # | CA1: Win | CB1: # | CC1: Mode | CD1: # | CE1: Target | CF1: # | CG1: Type | CH1: # | CI1: Color scale
B2: Window / Overlap | C2: 1 | D2: =VLOOKUP(C2,Win,2,0) -> 60/30 | BZ2: 1 | CA2: 60/30 | CB2: 1 | CC2: windowed | CD2: 1 | CE2: valence | CF2: 1 | CG2: input/model | CH2: 1 | CI2: no
BZ3: 2 | CA3: 60/15 | CB3: 2 | CC3: aggregated | CD3: 2 | CE3: arousal | CF3: 2 | CG3: best overall | CH3: 2 | CI3: accuracy
B4: Input Mode | C4: 2 | D4: =VLOOKUP(C4,InputMode,2,0) -> aggregated | BZ4: 3 | CA4: 60/0 | CH4: 3 | CI4: balanced accuracy
BZ5: 4 | CA5: 45/22.5 | CH5: 4 | CI5: precision
B6: Target | C6: 2 | D6: =VLOOKUP(C6,Target,2,0) -> arousal | BZ6: 5 | CA6: 45/11.25 | CH6: 5 | CI6: recall
BZ7: 6 | CA7: 45/0 | CH7: 6 | CI7: f1
B8: Best Comparison | C8: 2 | BZ8: 7 | CA8: 30/15
BZ9: 8 | CA9: 30/7.5
B10: Color Scale | C10: 2 | BZ10: 9 | CA10: 30/0
B12: Model | C12: HC | M12: NVG | W12: HVG | AG12: HC+NVG | AQ12: HC+HVG
C13: Accuracy | D13: IsM | E13: Balanced Accuracy | F13: IsM | G13: Precision | H13: IsM | I13: Recall | J13: IsM | K13: F1 | L13: IsM | M13: Accuracy | N13: IsM | O13: Balanced Accuracy | P13: IsM | Q13: Precision | R13: IsM | S13: Recall | T13: IsM | U13: F1 | V13: IsM | W13: Accuracy | X13: IsM | Y13: Balanced Accuracy | Z13: IsM | AA13: Precision | AB13: IsM | AC13: Recall | AD13: IsM | AE13: F1 | AF13: IsM | AG13: Accuracy | AH13: IsM | AI13: Balanced Accuracy | AJ13: IsM | AK13: Precision | AL13: IsM | AM13: Recall | AN13: IsM | AO13: F1 | AP13: IsM | AQ13: Accuracy | AR13: IsM | AS13: Balanced Accuracy | AT13: IsM | AU13: Precision | AV13: IsM | AW13: Recall | AX13: IsM | AY13: F1
B14: RF | C14: =IF(SUMIFS(DATA!$T:$T,DATA!$H:$H,LOWER($B14),DATA!$C:$C,_xlfn.NUMBERVALUE(LEFT($D$2,2)),DATA!$D:$D,_xlfn.NUMBERVALUE(MID($D$2,FIND("/",$D$2)+1,LEN($D$2))),DATA!$E:$E,$D$6,DATA!$F:$F,$D$4,DATA!$G:$G,LOWER(C$12))=0,"-",SUMIFS(DATA!$T:$T,DATA!$H:$H,LOWER($B14),DATA!$C:$C,_xlfn.NUMBERVALUE(LEFT($D$2,2)),DATA!$D:$D,_xlfn.NUMBERVALUE(MID($D$2,FIND("/",$D$2)+1,LEN($D$2))),DATA!$E:$E,$D$6,DATA!$F:$F,$D$4,DATA!$G:$G,LOWER(C$12))) -> 0.46402878 | D14: =IF($C$8=1,AND(MAX($C14,$M14,$W14,$AG14,$AQ14)=C14,C14<>0),AND(MAX($C$14:$C$20,$M$14:$M$20,$W$14:$W$20,$AG$14:$AG$20,$AQ$14:$AQ$20)=C14,C14<>0)) -> FALSE | E14: =IF(SUMIFS(DATA!$U:$U,DATA!$H:$H,LOWER($B14),DATA!$C:$C,_xlfn.NUMBERVALUE(LEFT($D$2,2)),DATA!$D:$D,_xlfn.NUMBERVALUE(MID($D$2,FIND("/",$D$2)+1,LEN($D$2))),DATA!$E:$E,$D$6,DATA!$F:$F,$D$4,DATA!$G:$G,LOWER(C$12))=0,"-",SUMIFS(DATA!$U:$U,DATA!$H:$H,LOWER($B14),DATA!$C:$C,_xlfn.NUMBERVALUE(LEFT($D$2,2)),DATA!$D:$D,_xlfn.NUMBERVALUE(MID($D$2,FIND("/",$D$2)+1,LEN($D$2))),DATA!$E:$E,$D$6,DATA!$F:$F,$D$4,DATA!$G:$G,LOWER(C$12))) -> 0.45405955 | F14: =IF($C$8=1,AND(MAX($E14,$O14,$Y14,$AI14,$AS14)=E14,E14<>0),AND(MAX($E$14:$E$20,$O$14:$O$20,$Y$14:$Y$20,$AI$14:$AI$20,$AS$14:$AS$14)=E14,E14<>0)) -> FALSE | G14: =IF(SUMIFS(DATA!$V:$V,DATA!$H:$H,LOWER($B14),DATA!$C:$C,_xlfn.NUMBERVALUE(LEFT($D$2,2)),DATA!$D:$D,_xlfn.NUMBERVALUE(MID($D$2,FIND("/",$D$2)+1,LEN($D$2))),DATA!$E:$E,$D$6,DATA!$F:$F,$D$4,DATA!$G:$G,LOWER(C$12))=0,"-",SUMIFS(DATA!$V:$V,DATA!$H:$H,LOWER($B14),DATA!$C:$C,_xlfn.NUMBERVALUE(LEFT($D$2,2)),DATA!$D:$D,_xlfn.NUMBERVALUE(MID($D$2,FIND("/",$D$2)+1,LEN($D$2))),DATA!$E:$E,$D$6,DATA!$F:$F,$D$4,DATA!$G:$G,LOWER(C$12))) -> 0.45201525 | H14: =IF($C$8=1,AND(MAX($G14,$Q14,$AA14,$AK14,$AU14)=G14,G14<>0),AND(MAX($G$14:$G$20,$Q$14:$Q$20,$AA$14:$AA$20,$AK$14:$AK$20,$AU$14:$AU$20)=G14,G14<>0)) -> FALSE | I14: =IF(SUMIFS(DATA!$W:$W,DATA!$H:$H,LOWER($B14),DATA!$C:$C,_xlfn.NUMBERVALUE(LEFT($D$2,2)),DATA!$D:$D,_xlfn.NUMBERVALUE(MID($D$2,FIND("/",$D$2)+1,LEN($D$2))),DATA!$E:$E,$D$6,DATA!$F:$F,$D$4,DATA!$G:$G,LOWER(C$12))=0,"-",SUMIFS(DATA!$W:$W,DATA!$H:$H,LOWER($B14),DATA!$C:$C,_xlfn.NUMBERVALUE(LEFT($D$2,2)),DATA!$D:$D,_xlfn.NUMBERVALUE(MID($D$2,FIND("/",$D$2)+1,LEN($D$2))),DATA!$E:$E,$D$6,DATA!$F:$F,$D$4,DATA!$G:$G,LOWER(C$12))) -> 0.45405955 | J14: =IF(SUMIFS(DATA!$W:$W,DATA!$H:$H,LOWER($B14),DATA!$C:$C,_xlfn.NUMBERVALUE(LEFT($D$2,2)),DATA!$D:$D,_xlfn.NUMBERVALUE(MID($D$2,FIND("/",$D$2)+1,LEN($D$2))),DATA!$E:$E,$D$6,DATA!$F:$F,$D$4,DATA!$G:$G,LOWER(D$12))=0,"-",SUMIFS(DATA!$W:$W,DATA!$H:$H,LOWER($B14),DATA!$C:$C,_xlfn.NUMBERVALUE(LEFT($D$2,2)),DATA!$D:$D,_xlfn.NUMBERVALUE(MID($D$2,FIND("/",$D$2)+1,LEN($D$2))),DATA!$E:$E,$D$6,DATA!$F:$F,$D$4,DATA!$G:$G,LOWER(D$12))) -> - | K14: =IF(SUMIFS(DATA!$X:$X,DATA!$H:$H,LOWER($B14),DATA!$C:$C,_xlfn.NUMBERVALUE(LEFT($D$2,2)),DATA!$D:$D,_xlfn.NUMBERVALUE(MID($D$2,FIND("/",$D$2)+1,LEN($D$2))),DATA!$E:$E,$D$6,DATA!$F:$F,$D$4,DATA!$G:$G,LOWER(C$12))=0,"-",SUMIFS(DATA!$X:$X,DATA!$H:$H,LOWER($B14),DATA!$C:$C,_xlfn.NUMBERVALUE(LEFT($D$2,2)),DATA!$D:$D,_xlfn.NUMBERVALUE(MID($D$2,FIND("/",$D$2)+1,LEN($D$2))),DATA!$E:$E,$D$6,DATA!$F:$F,$D$4,DATA!$G:$G,LOWER(C$12))) -> 0.4508915 | L14: =IF($C$8=1,AND(MAX($K14,$U14,$AE14,$AO14,$AY14)=K14,K14<>0),AND(MAX($K$14:$K$20,$U$14:$U$20,$AE$14:$AE$20,$AO$14:$AO$20,$AY$14:$AY$20)=K14,K14<>0)) -> FALSE | M14: =IF(SUMIFS(DATA!$T:$T,DATA!$H:$H,LOWER($B14),DATA!$C:$C,_xlfn.NUMBERVALUE(LEFT($D$2,2)),DATA!$D:$D,_xlfn.NUMBERVALUE(MID($D$2,FIND("/",$D$2)+1,LEN($D$2))),DATA!$E:$E,$D$6,DATA!$F:$F,$D$4,DATA!$G:$G,LOWER(M$12))=0,"-",SUMIFS(DATA!$T:$T,DATA!$H:$H,LOWER($B14),DATA!$C:$C,_xlfn.NUMBERVALUE(LEFT($D$2,2)),DATA!$D:$D,_xlfn.NUMBERVALUE(MID($D$2,FIND("/",$D$2)+1,LEN($D$2))),DATA!$E:$E,$D$6,DATA!$F:$F,$D$4,DATA!$G:$G,LOWER(M$12))) -> 0.5 | N14: =IF($C$8=1,AND(MAX($C14,$M14,$W14,$AG14,$AQ14)=M14,M14<>0),AND(MAX($C$14:$C$20,$M$14:$M$20,$W$14:$W$20,$AG$14:$AG$20,$AQ$14:$AQ$20)=M14,M14<>0)) -> FALSE | O14: =IF(SUMIFS(DATA!$U:$U,DATA!$H:$H,LOWER($B14),DATA!$C:$C,_xlfn.NUMBERVALUE(LEFT($D$2,2)),DATA!$D:$D,_xlfn.NUMBERVALUE(MID($D$2,FIND("/",$D$2)+1,LEN($D$2))),DATA!$E:$E,$D$6,DATA!$F:$F,$D$4,DATA!$G:$G,LOWER(M$12))=0,"-",SUMIFS(DATA!$U:$U,DATA!$H:$H,LOWER($B14),DATA!$C:$C,_xlfn.NUMBERVALUE(LEFT($D$2,2)),DATA!$D:$D,_xlfn.NUMBERVALUE(MID($D$2,FIND("/",$D$2)+1,LEN($D$2))),DATA!$E:$E,$D$6,DATA!$F:$F,$D$4,DATA!$G:$G,LOWER(M$12))) -> 0.48779788 | P14: =IF($C$8=1,AND(MAX($E14,$O14,$Y14,$AI14,$AS14)=O14,O14<>0),AND(MAX($E$14:$E$20,$O$14:$O$20,$Y$14:$Y$20,$AI$14:$AI$20,$AS$14:$AS$14)=O14,O14<>0)) -> FALSE | Q14: =IF(SUMIFS(DATA!$V:$V,DATA!$H:$H,LOWER($B14),DATA!$C:$C,_xlfn.NUMBERVALUE(LEFT($D$2,2)),DATA!$D:$D,_xlfn.NUMBERVALUE(MID($D$2,FIND("/",$D$2)+1,LEN($D$2))),DATA!$E:$E,$D$6,DATA!$F:$F,$D$4,DATA!$G:$G,LOWER(M$12))=0,"-",SUMIFS(DATA!$V:$V,DATA!$H:$H,LOWER($B14),DATA!$C:$C,_xlfn.NUMBERVALUE(LEFT($D$2,2)),DATA!$D:$D,_xlfn.NUMBERVALUE(MID($D$2,FIND("/",$D$2)+1,LEN($D$2))),DATA!$E:$E,$D$6,DATA!$F:$F,$D$4,DATA!$G:$G,LOWER(M$12))) -> 0.48685393 | R14: =IF($C$8=1,AND(MAX($G14,$Q14,$AA14,$AK14,$AU14)=Q14,Q14<>0),AND(MAX($G$14:$G$20,$Q$14:$Q$20,$AA$14:$AA$20,$AK$14:$AK$20,$AU$14:$AU$20)=Q14,Q14<>0)) -> FALSE | S14: =IF(SUMIFS(DATA!$W:$W,DATA!$H:$H,LOWER($B14),DATA!$C:$C,_xlfn.NUMBERVALUE(LEFT($D$2,2)),DATA!$D:$D,_xlfn.NUMBERVALUE(MID($D$2,FIND("/",$D$2)+1,LEN($D$2))),DATA!$E:$E,$D$6,DATA!$F:$F,$D$4,DATA!$G:$G,LOWER(M$12))=0,"-",SUMIFS(DATA!$W:$W,DATA!$H:$H,LOWER($B14),DATA!$C:$C,_xlfn.NUMBERVALUE(LEFT($D$2,2)),DATA!$D:$D,_xlfn.NUMBERVALUE(MID($D$2,FIND("/",$D$2)+1,LEN($D$2))),DATA!$E:$E,$D$6,DATA!$F:$F,$D$4,DATA!$G:$G,LOWER(M$12))) -> 0.48779788 | T14: =IF($C$8=1,AND(MAX($I14,$S14,$AC14,$AM14,$AW14)=S14,S14<>0),AND(MAX($I$14:$I$20,$S$14:$S$20,$AC$14:$AC$20,$AM$14:$AM$20,$AW$14:$AW$20)=S14,S14<>0)) -> FALSE | U14: =IF(SUMIFS(DATA!$X:$X,DATA!$H:$H,LOWER($B14),DATA!$C:$C,_xlfn.NUMBERVALUE(LEFT($D$2,2)),DATA!$D:$D,_xlfn.NUMBERVALUE(MID($D$2,FIND("/",$D$2)+1,LEN($D$2))),DATA!$E:$E,$D$6,DATA!$F:$F,$D$4,DATA!$G:$G,LOWER(M$12))=0,"-",SUMIFS(DATA!$X:$X,DATA!$H:$H,LOWER($B14),DATA!$C:$C,_xlfn.NUMBERVALUE(LEFT($D$2,2)),DATA!$D:$D,_xlfn.NUMBERVALUE(MID($D$2,FIND("/",$D$2)+1,LEN($D$2))),DATA!$E:$E,$D$6,DATA!$F:$F,$D$4,DATA!$G:$G,LOWER(M$12))) -> 0.4825864 | V14: =IF($C$8=1,AND(MAX($K14,$U14,$AE14,$AO14,$AY14)=U14,U14<>0),AND(MAX($K$14:$K$20,$U$14:$U$20,$AE$14:$AE$20,$AO$14:$AO$20,$AY$14:$AY$20)=U14,U14<>0)) -> FALSE | W14: =IF(SUMIFS(DATA!$T:$T,DATA!$H:$H,LOWER($B14),DATA!$C:$C,_xlfn.NUMBERVALUE(LEFT($D$2,2)),DATA!$D:$D,_xlfn.NUMBERVALUE(MID($D$2,FIND("/",$D$2)+1,LEN($D$2))),DATA!$E:$E,$D$6,DATA!$F:$F,$D$4,DATA!$G:$G,LOWER(W$12))=0,"-",SUMIFS(DATA!$T:$T,DATA!$H:$H,LOWER($B14),DATA!$C:$C,_xlfn.NUMBERVALUE(LEFT($D$2,2)),DATA!$D:$D,_xlfn.NUMBERVALUE(MID($D$2,FIND("/",$D$2)+1,LEN($D$2))),DATA!$E:$E,$D$6,DATA!$F:$F,$D$4,DATA!$G:$G,LOWER(W$12))) -> 0.48920863 | X14: =IF($C$8=1,AND(MAX($C14,$M14,$W14,$AG14,$AQ14)=W14,W14<>0),AND(MAX($C$14:$C$20,$M$14:$M$20,$W$14:$W$20,$AG$14:$AG$20,$AQ$14:$AQ$20)=W14,W14<>0)) -> FALSE | Y14: =IF(SUMIFS(DATA!$U:$U,DATA!$H:$H,LOWER($B14),DATA!$C:$C,_xlfn.NUMBERVALUE(LEFT($D$2,2)),DATA!$D:$D,_xlfn.NUMBERVALUE(MID($D$2,FIND("/",$D$2)+1,LEN($D$2))),DATA!$E:$E,$D$6,DATA!$F:$F,$D$4,DATA!$G:$G,LOWER(W$12))=0,"-",SUMIFS(DATA!$U:$U,DATA!$H:$H,LOWER($B14),DATA!$C:$C,_xlfn.NUMBERVALUE(LEFT($D$2,2)),DATA!$D:$D,_xlfn.NUMBERVALUE(MID($D$2,FIND("/",$D$2)+1,LEN($D$2))),DATA!$E:$E,$D$6,DATA!$F:$F,$D$4,DATA!$G:$G,LOWER(W$12))) -> 0.4828701 | Z14: =IF($C$8=1,AND(MAX($E14,$O14,$Y14,$AI14,$AS14)=Y14,Y14<>0),AND(MAX($E$14:$E$20,$O$14:$O$20,$Y$14:$Y$20,$AI$14:$AI$20,$AS$14:$AS$14)=Y14,Y14<>0)) -> FALSE | AA14: =IF(SUMIFS(DATA!$V:$V,DATA!$H:$H,LOWER($B14),DATA!$C:$C,_xlfn.NUMBERVALUE(LEFT($D$2,2)),DATA!$D:$D,_xlfn.NUMBERVALUE(MID($D$2,FIND("/",$D$2)+1,LEN($D$2))),DATA!$E:$E,$D$6,DATA!$F:$F,$D$4,DATA!$G:$G,LOWER(W$12))=0,"-",SUMIFS(DATA!$V:$V,DATA!$H:$H,LOWER($B14),DATA!$C:$C,_xlfn.NUMBERVALUE(LEFT($D$2,2)),DATA!$D:$D,_xlfn.NUMBERVALUE(MID($D$2,FIND("/",$D$2)+1,LEN($D$2))),DATA!$E:$E,$D$6,DATA!$F:$F,$D$4,DATA!$G:$G,LOWER(W$12))) -> 0.48263834 | AB14: =IF($C$8=1,AND(MAX($G14,$Q14,$AA14,$AK14,$AU14)=AA14,AA14<>0),AND(MAX($G$14:$G$20,$Q$14:$Q$20,$AA$14:$AA$20,$AK$14:$AK$20,$AU$14:$AU$20)=AA14,AA14<>0)) -> FALSE | AC14: =IF(SUMIFS(DATA!$W:$W,DATA!$H:$H,LOWER($B14),DATA!$C:$C,_xlfn.NUMBERVALUE(LEFT($D$2,2)),DATA!$D:$D,_xlfn.NUMBERVALUE(MID($D$2,FIND("/",$D$2)+1,LEN($D$2))),DATA!$E:$E,$D$6,DATA!$F:$F,$D$4,DATA!$G:$G,LOWER(W$12))=0,"-",SUMIFS(DATA!$W:$W,DATA!$H:$H,LOWER($B14),DATA!$C:$C,_xlfn.NUMBERVALUE(LEFT($D$2,2)),DATA!$D:$D,_xlfn.NUMBERVALUE(MID($D$2,FIND("/",$D$2)+1,LEN($D$2))),DATA!$E:$E,$D$6,DATA!$F:$F,$D$4,DATA!$G:$G,LOWER(W$12))) -> 0.4828701 | AD14: =IF($C$8=1,AND(MAX($I14,$S14,$AC14,$AM14,$AW14)=AC14,AC14<>0),AND(MAX($I$14:$I$20,$S$14:$S$20,$AC$14:$AC$20,$AM$14:$AM$20,$AW$14:$AW$20)=AC14,AC14<>0)) -> FALSE | AE14: =IF(SUMIFS(DATA!$X:$X,DATA!$H:$H,LOWER($B14),DATA!$C:$C,_xlfn.NUMBERVALUE(LEFT($D$2,2)),DATA!$D:$D,_xlfn.NUMBERVALUE(MID($D$2,FIND("/",$D$2)+1,LEN($D$2))),DATA!$E:$E,$D$6,DATA!$F:$F,$D$4,DATA!$G:$G,LOWER(W$12))=0,"-",SUMIFS(DATA!$X:$X,DATA!$H:$H,LOWER($B14),DATA!$C:$C,_xlfn.NUMBERVALUE(LEFT($D$2,2)),DATA!$D:$D,_xlfn.NUMBERVALUE(MID($D$2,FIND("/",$D$2)+1,LEN($D$2))),DATA!$E:$E,$D$6,DATA!$F:$F,$D$4,DATA!$G:$G,LOWER(W$12))) -> 0.48234986 | AF14: =IF($C$8=1,AND(MAX($K14,$U14,$AE14,$AO14,$AY14)=AE14,AE14<>0),AND(MAX($K$14:$K$20,$U$14:$U$20,$AE$14:$AE$20,$AO$14:$AO$20,$AY$14:$AY$20)=AE14,AE14<>0)) -> FALSE | AG14: =IF(SUMIFS(DATA!$T:$T,DATA!$H:$H,LOWER($B14),DATA!$C:$C,_xlfn.NUMBERVALUE(LEFT($D$2,2)),DATA!$D:$D,_xlfn.NUMBERVALUE(MID($D$2,FIND("/",$D$2)+1,LEN($D$2))),DATA!$E:$E,$D$6,DATA!$F:$F,$D$4,DATA!$G:$G,LOWER(AG$12))=0,"-",SUMIFS(DATA!$T:$T,DATA!$H:$H,LOWER($B14),DATA!$C:$C,_xlfn.NUMBERVALUE(LEFT($D$2,2)),DATA!$D:$D,_xlfn.NUMBERVALUE(MID($D$2,FIND("/",$D$2)+1,LEN($D$2))),DATA!$E:$E,$D$6,DATA!$F:$F,$D$4,DATA!$G:$G,LOWER(AG$12))) -> 0.5 | AH14: =IF($C$8=1,AND(MAX($C14,$M14,$W14,$AG14,$AQ14)=AG14,AG14<>0),AND(MAX($C$14:$C$20,$M$14:$M$20,$W$14:$W$20,$AG$14:$AG$20,$AQ$14:$AQ$20)=AG14,AG14<>0)) -> FALSE | AI14: =IF(SUMIFS(DATA!$U:$U,DATA!$H:$H,LOWER($B14),DATA!$C:$C,_xlfn.NUMBERVALUE(LEFT($D$2,2)),DATA!$D:$D,_xlfn.NUMBERVALUE(MID($D$2,FIND("/",$D$2)+1,LEN($D$2))),DATA!$E:$E,$D$6,DATA!$F:$F,$D$4,DATA!$G:$G,LOWER(AG$12))=0,"-",SUMIFS(DATA!$U:$U,DATA!$H:$H,LOWER($B14),DATA!$C:$C,_xlfn.NUMBERVALUE(LEFT($D$2,2)),DATA!$D:$D,_xlfn.NUMBERVALUE(MID($D$2,FIND("/",$D$2)+1,LEN($D$2))),DATA!$E:$E,$D$6,DATA!$F:$F,$D$4,DATA!$G:$G,LOWER(AG$12))) -> 0.48717213 | AJ14: =IF($C$8=1,AND(MAX($E14,$O14,$Y14,$AI14,$AS14)=AI14,AI14<>0),AND(MAX($E$14:$E$20,$O$14:$O$20,$Y$14:$Y$20,$AI$14:$AI$20,$AS$14:$AS$14)=AI14,AI14<>0)) -> FALSE | AK14: =IF(SUMIFS(DATA!$V:$V,DATA!$H:$H,LOWER($B14),DATA!$C:$C,_xlfn.NUMBERVALUE(LEFT($D$2,2)),DATA!$D:$D,_xlfn.NUMBERVALUE(MID($D$2,FIND("/",$D$2)+1,LEN($D$2))),DATA!$E:$E,$D$6,DATA!$F:$F,$D$4,DATA!$G:$G,LOWER(AG$12))=0,"-",SUMIFS(DATA!$V:$V,DATA!$H:$H,LOWER($B14),DATA!$C:$C,_xlfn.NUMBERVALUE(LEFT($D$2,2)),DATA!$D:$D,_xlfn.NUMBERVALUE(MID($D$2,FIND("/",$D$2)+1,LEN($D$2))),DATA!$E:$E,$D$6,DATA!$F:$F,$D$4,DATA!$G:$G,LOWER(AG$12))) -> 0.48605442 | AL14: =IF($C$8=1,AND(MAX($G14,$Q14,$AA14,$AK14,$AU14)=AK14,AK14<>0),AND(MAX($G$14:$G$20,$Q$14:$Q$20,$AA$14:$AA$20,$AK$14:$AK$20,$AU$14:$AU$20)=AK14,AK14<>0)) -> FALSE | AM14: =IF(SUMIFS(DATA!$W:$W,DATA!$H:$H,LOWER($B14),DATA!$C:$C,_xlfn.NUMBERVALUE(LEFT($D$2,2)),DATA!$D:$D,_xlfn.NUMBERVALUE(MID($D$2,FIND("/",$D$2)+1,LEN($D$2))),DATA!$E:$E,$D$6,DATA!$F:$F,$D$4,DATA!$G:$G,LOWER(AG$12))=0,"-",SUMIFS(DATA!$W:$W,DATA!$H:$H,LOWER($B14),DATA!$C:$C,_xlfn.NUMBERVALUE(LEFT($D$2,2)),DATA!$D:$D,_xlfn.NUMBERVALUE(MID($D$2,FIND("/",$D$2)+1,LEN($D$2))),DATA!$E:$E,$D$6,DATA!$F:$F,$D$4,DATA!$G:$G,LOWER(AG$12))) -> 0.48717213 | AN14: =IF($C$8=1,AND(MAX($I14,$S14,$AC14,$AM14,$AW14)=AM14,AM14<>0),AND(MAX($I$14:$I$20,$S$14:$S$20,$AC$14:$AC$20,$AM$14:$AM$20,$AW$14:$AW$20)=AM14,AM14<>0)) -> FALSE | AO14: =IF(SUMIFS(DATA!$X:$X,DATA!$H:$H,LOWER($B14),DATA!$C:$C,_xlfn.NUMBERVALUE(LEFT($D$2,2)),DATA!$D:$D,_xlfn.NUMBERVALUE(MID($D$2,FIND("/",$D$2)+1,LEN($D$2))),DATA!$E:$E,$D$6,DATA!$F:$F,$D$4,DATA!$G:$G,LOWER(AG$12))=0,"-",SUMIFS(DATA!$X:$X,DATA!$H:$H,LOWER($B14),DATA!$C:$C,_xlfn.NUMBERVALUE(LEFT($D$2,2)),DATA!$D:$D,_xlfn.NUMBERVALUE(MID($D$2,FIND("/",$D$2)+1,LEN($D$2))),DATA!$E:$E,$D$6,DATA!$F:$F,$D$4,DATA!$G:$G,LOWER(AG$12))) -> 0.48114132 | AP14: =IF($C$8=1,AND(MAX($K14,$U14,$AE14,$AO14,$AY14)=AO14,AO14<>0),AND(MAX($K$14:$K$20,$U$14:$U$20,$AE$14:$AE$20,$AO$14:$AO$20,$AY$14:$AY$20)=AO14,AO14<>0)) -> FALSE | AQ14: =IF(SUMIFS(DATA!$T:$T,DATA!$H:$H,LOWER($B14),DATA!$C:$C,_xlfn.NUMBERVALUE(LEFT($D$2,2)),DATA!$D:$D,_xlfn.NUMBERVALUE(MID($D$2,FIND("/",$D$2)+1,LEN($D$2))),DATA!$E:$E,$D$6,DATA!$F:$F,$D$4,DATA!$G:$G,LOWER(AQ$12))=0,"-",SUMIFS(DATA!$T:$T,DATA!$H:$H,LOWER($B14),DATA!$C:$C,_xlfn.NUMBERVALUE(LEFT($D$2,2)),DATA!$D:$D,_xlfn.NUMBERVALUE(MID($D$2,FIND("/",$D$2)+1,LEN($D$2))),DATA!$E:$E,$D$6,DATA!$F:$F,$D$4,DATA!$G:$G,LOWER(AQ$12))) -> 0.48920863 | AR14: =IF($C$8=1,AND(MAX($C14,$M14,$W14,$AG14,$AQ14)=AQ14,AQ14<>0),AND(MAX($C$14:$C$20,$M$14:$M$20,$W$14:$W$20,$AG$14:$AG$20,$AQ$14:$AQ$20)=AQ14,AQ14<>0)) -> FALSE | AS14: =IF(SUMIFS(DATA!$U:$U,DATA!$H:$H,LOWER($B14),DATA!$C:$C,_xlfn.NUMBERVALUE(LEFT($D$2,2)),DATA!$D:$D,_xlfn.NUMBERVALUE(MID($D$2,FIND("/",$D$2)+1,LEN($D$2))),DATA!$E:$E,$D$6,DATA!$F:$F,$D$4,DATA!$G:$G,LOWER(AQ$12))=0,"-",SUMIFS(DATA!$U:$U,DATA!$H:$H,LOWER($B14),DATA!$C:$C,_xlfn.NUMBERVALUE(LEFT($D$2,2)),DATA!$D:$D,_xlfn.NUMBERVALUE(MID($D$2,FIND("/",$D$2)+1,LEN($D$2))),DATA!$E:$E,$D$6,DATA!$F:$F,$D$4,DATA!$G:$G,LOWER(AQ$12))) -> 0.48099286 | AT14: =IF($C$8=1,AND(MAX($E14,$O14,$Y14,$AI14,$AS14)=AS14,AS14<>0),AND(MAX($E$14:$E$20,$O$14:$O$20,$Y$14:$Y$20,$AI$14:$AI$20,$AS$14:$AS$14)=AS14,AS14<>0)) -> FALSE | AU14: =IF(SUMIFS(DATA!$V:$V,DATA!$H:$H,LOWER($B14),DATA!$C:$C,_xlfn.NUMBERVALUE(LEFT($D$2,2)),DATA!$D:$D,_xlfn.NUMBERVALUE(MID($D$2,FIND("/",$D$2)+1,LEN($D$2))),DATA!$E:$E,$D$6,DATA!$F:$F,$D$4,DATA!$G:$G,LOWER(AQ$12))=0,"-",SUMIFS(DATA!$V:$V,DATA!$H:$H,LOWER($B14),DATA!$C:$C,_xlfn.NUMBERVALUE(LEFT($D$2,2)),DATA!$D:$D,_xlfn.NUMBERVALUE(MID($D$2,FIND("/",$D$2)+1,LEN($D$2))),DATA!$E:$E,$D$6,DATA!$F:$F,$D$4,DATA!$G:$G,LOWER(AQ$12))) -> 0.48045052 | AV14: =IF($C$8=1,AND(MAX($G14,$Q14,$AA14,$AK14,$AU14)=AU14,AU14<>0),AND(MAX($G$14:$G$20,$Q$14:$Q$20,$AA$14:$AA$20,$AK$14:$AK$20,$AU$14:$AU$20)=AU14,AU14<>0)) -> FALSE | AW14: =IF(SUMIFS(DATA!$W:$W,DATA!$H:$H,LOWER($B14),DATA!$C:$C,_xlfn.NUMBERVALUE(LEFT($D$2,2)),DATA!$D:$D,_xlfn.NUMBERVALUE(MID($D$2,FIND("/",$D$2)+1,LEN($D$2))),DATA!$E:$E,$D$6,DATA!$F:$F,$D$4,DATA!$G:$G,LOWER(AQ$12))=0,"-",SUMIFS(DATA!$W:$W,DATA!$H:$H,LOWER($B14),DATA!$C:$C,_xlfn.NUMBERVALUE(LEFT($D$2,2)),DATA!$D:$D,_xlfn.NUMBERVALUE(MID($D$2,FIND("/",$D$2)+1,LEN($D$2))),DATA!$E:$E,$D$6,DATA!$F:$F,$D$4,DATA!$G:$G,LOWER(AQ$12))) -> 0.48099286 | AX14: =IF($C$8=1,AND(MAX($I14,$S14,$AC14,$AM14,$AW14)=AW14,AW14<>0),AND(MAX($I$14:$I$20,$S$14:$S$20,$AC$14:$AC$20,$AM$14:$AM$20,$AW$14:$AW$20)=AW14,AW14<>0)) -> FALSE | AY14: =IF(SUMIFS(DATA!$X:$X,DATA!$H:$H,LOWER($B14),DATA!$C:$C,_xlfn.NUMBERVALUE(LEFT($D$2,2)),DATA!$D:$D,_xlfn.NUMBERVALUE(MID($D$2,FIND("/",$D$2)+1,LEN($D$2))),DATA!$E:$E,$D$6,DATA!$F:$F,$D$4,DATA!$G:$G,LOWER(AQ$12))=0,"-",SUMIFS(DATA!$X:$X,DATA!$H:$H,LOWER($B14),DATA!$C:$C,_xlfn.NUMBERVALUE(LEFT($D$2,2)),DATA!$D:$D,_xlfn.NUMBERVALUE(MID($D$2,FIND("/",$D$2)+1,LEN($D$2))),DATA!$E:$E,$D$6,DATA!$F:$F,$D$4,DATA!$G:$G,LOWER(AQ$12))) -> 0.47948312 | AZ14: =IF($C$8=1,AND(MAX($K14,$U14,$AE14,$AO14,$AY14)=AY14,AY14<>0),AND(MAX($K$14:$K$20,$U$14:$U$20,$AE$14:$AE$20,$AO$14:$AO$20,$AY$14:$AY$20)=AY14,AY14<>0)) -> FALSE
