Workbook
Name Class: Results!$BZ$2:$CA$4
Name InputMode: Results!$BR$2:$BS$3
Name Target: Results!$BT$2:$BU$3
Name Win: Results!$BP$2:$BQ$10

Sheet DATA
A1: experiment_id | B1: dataset_id | C1: target | D1: task_kind | E1: candidate_id | F1: candidate_order | G1: input_id | H1: input_mode | I1: representation | J1: model | K1: evaluation_unit | L1: total_candidate_count | M1: common_trial_count | N1: subjects_total | O1: outer_folds_run | P1: complete_loso | Q1: primary_metric | R1: primary_score | S1: primary_evaluable_subjects | T1: primary_excluded_subjects | U1: best_parameter_counts_json | V1: most_frequent_parameters_json | W1: parameter_stability_fraction | X1: quick_grid | Y1: inner_fit_seconds | Z1: outer_fit_seconds | AA1: target_run_seconds | AB1: n_samples | AC1: classes_observed | AD1: accuracy | AE1: balanced_accuracy | AF1: macro_precision | AG1: macro_recall | AH1: macro_f1 | AI1: mcc | AJ1: confusion_matrix_json | AK1: roc_auc | AL1: average_precision | AM1: support__low | AN1: precision__low | AO1: recall__low | AP1: f1__low | AQ1: support__high | AR1: precision__high | AS1: recall__high | AT1: f1__high | AU1: tn | AV1: fp | AW1: fn | AX1: tp | AY1: bootstrap_repeats | AZ1: accuracy_ci_low | BA1: accuracy_ci_high | BB1: balanced_accuracy_ci_low | BC1: balanced_accuracy_ci_high | BD1: macro_f1_ci_low | BE1: macro_f1_ci_high | BF1: mcc_ci_low | BG1: mcc_ci_high | BH1: primary_score_bootstrap_valid_repeats | BI1: primary_score_ci_low | BJ1: primary_score_ci_high | BK1: primary_rank_within_target
A2: nested__physiological_features__valence__binary__knn__windowed__hc__emognition_features_w60_o30 | B2: physiological_features | C2: valence | D2: binary | E2: knn__windowed__hc__emognition_features_w60_o30 | F2: 0 | G2: emognition_features_w60_o30 | H2: windowed | I2: hc | J2: knn | K2: trial | L2: 10 | M2: 304 | N2: 42 | O2: 42 | P2: TRUE | Q2: subject_class_macro_recall | R2: 0.47142511 | S2: 42 | T2: 0 | U2: {"{\"clf__n_neighbors\": 3, \"clf__p\": 2, \"clf__weights\": \"distance\"}": 15, "{\"clf__n_neighbors\": 5, \"clf__p\": 2, \"clf__weights\": \"distance\"}": 14, "{\"clf__n_neighbors\": 9, \"clf__p\": 2, \"clf__weights\": \"distance\"}": 11, "{\"clf__n_neighbors\": 9, \"clf__p\": 2, \"clf__weights\": \"uniform\"}": 2} | V2: {"clf__n_neighbors": 3, "clf__p": 2, "clf__weights": "distance"} | W2: 0.35714286 | X2: FALSE | Y2: 5.8496913 | Z2: 0.3749983 | AA2: 680.89589 | AB2: 304 | AC2: 2 | AD2: 0.47039474 | AE2: 0.47099303 | AF2: 0.47116259 | AG2: 0.47099303 | AH2: 0.46993015 | AI2: -0.057844131 | AJ2: [[67, 73], [88, 76]] | AK2: 0.4768946 | AL2: 0.52855781 | AM2: 140 | AN2: 0.43225806 | AO2: 0.47857143 | AP2: 0.45423729 | AQ2: 164 | AR2: 0.51006711 | AS2: 0.46341463 | AT2: 0.485623 | AU2: 67 | AV2: 73 | AW2: 88 | AX2: 76 | AY2: 1000 | AZ2: 0.41209765 | BA2: 0.52921951 | BB2: 0.41024842 | BC2: 0.53075673 | BD2: 0.40916976 | BE2: 0.52779129 | BF2: -0.17847112 | BG2: 0.061271944 | BH2: 1000 | BI2: 0.41027586 | BJ2: 0.52986396 | BK2: 8
A3: nested__physiological_features__valence__binary__knn__windowed__nvg__emognition_features_w60_o30 | B3: physiological_features | C3: valence | D3: binary | E3: knn__windowed__nvg__emognition_features_w60_o30 | F3: 1 | G3: emognition_features_w60_o30 | H3: windowed | I3: nvg | J3: knn | K3: trial | L3: 10 | M3: 304 | N3: 42 | O3: 42 | P3: TRUE | Q3: subject_class_macro_recall | R3: 0.53364167 | S3: 42 | T3: 0 | U3: {"{\"clf__n_neighbors\": 3, \"clf__p\": 2, \"clf__weights\": \"distance\"}": 6, "{\"clf__n_neighbors\": 3, \"clf__p\": 2, \"clf__weights\": \"uniform\"}": 1, "{\"clf__n_neighbors\": 5, \"clf__p\": 2, \"clf__weights\": \"distance\"}": 8, "{\"clf__n_neighbors\": 5, \"clf__p\": 2, \"clf__weights\": \"uniform\"}": 2, "{\"clf__n_neighbors\": 9, \"clf__p\": 2, \"clf__weights\": \"distance\"}": 19, "{\"clf__n_neighbors\": 9, \"clf__p\": 2, \"clf__weights\": \"uniform\"}": 6} | V3: {"clf__n_neighbors": 9, "clf__p": 2, "clf__weights": "distance"} | W3: 0.45238095 | X3: FALSE | Y3: 6.0303093 | Z3: 0.3988312 | AA3: 742.63454 | AB3: 304 | AC3: 2 | AD3: 0.52631579 | AE3: 0.5228223 | AF3: 0.52287411 | AG3: 0.5228223 | AH3: 0.52282538 | AI3: 0.045696375 | AJ3: [[67, 73], [71, 93]] | AK3: 0.54272648 | AL3: 0.60380213 | AM3: 140 | AN3: 0.48550725 | AO3: 0.47857143 | AP3: 0.48201439 | AQ3: 164 | AR3: 0.56024096 | AS3: 0.56707317 | AT3: 0.56363636 | AU3: 67 | AV3: 73 | AW3: 71 | AX3: 93 | AY3: 1000 | AZ3: 0.46864686 | BA3: 0.58118945 | BB3: 0.46508353 | BC3: 0.57727794 | BD3: 0.46435661 | BE3: 0.57677258 | BF3: -0.070042291 | BG3: 0.15506529 | BH3: 1000 | BI3: 0.47585418 | BJ3: 0.58887613 | BK3: 3
A4: nested__physiological_features__valence__binary__knn__windowed__hvg__emognition_features_w60_o30 | B4: physiological_features | C4: valence | D4: binary | E4: knn__windowed__hvg__emognition_features_w60_o30 | F4: 2 | G4: emognition_features_w60_o30 | H4: windowed | I4: hvg | J4: knn | K4: trial | L4: 10 | M4: 304 | N4: 42 | O4: 42 | P4: TRUE | Q4: subject_class_macro_recall | R4: 0.46686854 | S4: 42 | T4: 0 | U4: {"{\"clf__n_neighbors\": 3, \"clf__p\": 2, \"clf__weights\": \"distance\"}": 18, "{\"clf__n_neighbors\": 3, \"clf__p\": 2, \"clf__weights\": \"uniform\"}": 3, "{\"clf__n_neighbors\": 5, \"clf__p\": 2, \"clf__weights\": \"distance\"}": 7, "{\"clf__n_neighbors\": 5, \"clf__p\": 2, \"clf__weights\": \"uniform\"}": 2, "{\"clf__n_neighbors\": 9, \"clf__p\": 2, \"clf__weights\": \"distance\"}": 10, "{\"clf__n_neighbors\": 9, \"clf__p\": 2, \"clf__weights\": \"uniform\"}": 2} | V4: {"clf__n_neighbors": 3, "clf__p": 2, "clf__weights": "distance"} | W4: 0.42857143 | X4: FALSE | Y4: 6.1542987 | Z4: 0.4024383 | AA4: 786.07025 | AB4: 304 | AC4: 2 | AD4: 0.49342105 | AE4: 0.48449477 | AF4: 0.48377984 | AG4: 0.48449477 | AH4: 0.48155039 | AI4: -0.031717327 | AJ4: [[52, 88], [66, 98]] | AK4: 0.4883493 | AL4: 0.54615284 | AM4: 140 | AN4: 0.44067797 | AO4: 0.37142857 | AP4: 0.40310078 | AQ4: 164 | AR4: 0.52688172 | AS4: 0.59756098 | AT4: 0.56 | AU4: 52 | AV4: 88 | AW4: 66 | AX4: 98 | AY4: 1000 | AZ4: 0.45236711 | BA4: 0.53770492 | BB4: 0.44039867 | BC4: 0.53242807 | BD4: 0.43627227 | BE4: 0.52990332 | BF4: -0.12268507 | BG4: 0.065733194 | BH4: 1000 | BI4: 0.42162287 | BJ4: 0.51666667 | BK4: 9
A5: nested__physiological_features__valence__binary__knn__windowed__hc+nvg__emognition_features_w60_o30 | B5: physiological_features | C5: valence | D5: binary | E5: knn__windowed__hc+nvg__emognition_features_w60_o30 | F5: 3 | G5: emognition_features_w60_o30 | H5: windowed | I5: hc+nvg | J5: knn | K5: trial | L5: 10 | M5: 304 | N5: 42 | O5: 42 | P5: TRUE | Q5: subject_class_macro_recall | R5: 0.52089279 | S5: 42 | T5: 0 | U5: {"{\"clf__n_neighbors\": 3, \"clf__p\": 2, \"clf__weights\": \"distance\"}": 4, "{\"clf__n_neighbors\": 3, \"clf__p\": 2, \"clf__weights\": \"uniform\"}": 2, "{\"clf__n_neighbors\": 5, \"clf__p\": 2, \"clf__weights\": \"distance\"}": 8, "{\"clf__n_neighbors\": 9, \"clf__p\": 2, \"clf__weights\": \"distance\"}": 25, "{\"clf__n_neighbors\": 9, \"clf__p\": 2, \"clf__weights\": \"uniform\"}": 3} | V5: {"clf__n_neighbors": 9, "clf__p": 2, "clf__weights": "distance"} | W5: 0.5952381 | X5: FALSE | Y5: 6.794537 | Z5: 0.4557774 | AA5: 845.41798 | AB5: 304 | AC5: 2 | AD5: 0.51315789 | AE5: 0.51167247 | AF5: 0.51161783 | AG5: 0.51167247 | AH5: 0.51144508 | AI5: 0.023290235 | AJ5: [[69, 71], [77, 87]] | AK5: 0.52676394 | AL5: 0.55977956 | AM5: 140 | AN5: 0.47260274 | AO5: 0.49285714 | AP5: 0.48251748 | AQ5: 164 | AR5: 0.55063291 | AS5: 0.5304878 | AT5: 0.54037267 | AU5: 69 | AV5: 71 | AW5: 77 | AX5: 87 | AY5: 1000 | AZ5: 0.4584683 | BA5: 0.56351792 | BB5: 0.4552085 | BC5: 0.56362702 | BD5: 0.45404258 | BE5: 0.56171135 | BF5: -0.089783489 | BG5: 0.12723957 | BH5: 1000 | BI5: 0.46870864 | BJ5: 0.56870536 | BK5: 7
A6: nested__physiological_features__valence__binary__knn__windowed__hc+hvg__emognition_features_w60_o30 | B6: physiological_features | C6: valence | D6: binary | E6: knn__windowed__hc+hvg__emognition_features_w60_o30 | F6: 4 | G6: emognition_features_w60_o30 | H6: windowed | I6: hc+hvg | J6: knn | K6: trial | L6: 10 | M6: 304 | N6: 42 | O6: 42 | P6: TRUE | Q6: subject_class_macro_recall | R6: 0.4632176 | S6: 42 | T6: 0 | U6: {"{\"clf__n_neighbors\": 3, \"clf__p\": 2, \"clf__weights\": \"distance\"}": 20, "{\"clf__n_neighbors\": 5, \"clf__p\": 2, \"clf__weights\": \"distance\"}": 7, "{\"clf__n_neighbors\": 9, \"clf__p\": 2, \"clf__weights\": \"distance\"}": 11, "{\"clf__n_neighbors\": 9, \"clf__p\": 2, \"clf__weights\": \"uniform\"}": 4} | V6: {"clf__n_neighbors": 3, "clf__p": 2, "clf__weights": "distance"} | W6: 0.47619048 | X6: FALSE | Y6: 6.8704603 | Z6: 0.5061275 | AA6: 897.1315 | AB6: 304 | AC6: 2 | AD6: 0.45065789 | AE6: 0.44538328 | AF6: 0.44486216 | AG6: 0.44538328 | AH6: 0.44488546 | AI6: -0.10975333 | AJ6: [[53, 87], [80, 84]] | AK6: 0.42665505 | AL6: 0.48893781 | AM6: 140 | AN6: 0.39849624 | AO6: 0.37857143 | AP6: 0.38827839 | AQ6: 164 | AR6: 0.49122807 | AS6: 0.51219512 | AT6: 0.50149254 | AU6: 53 | AV6: 87 | AW6: 80 | AX6: 84 | AY6: 1000 | AZ6: 0.39794506 | BA6: 0.50485596 | BB6: 0.39141264 | BC6: 0.50015648 | BD6: 0.39004788 | BE6: 0.49874068 | BF6: -0.21703842 | BG6: 0.00031813046 | BH6: 1000 | BI6: 0.40871528 | BJ6: 0.52083956 | BK6: 10
A7: nested__physiological_features__valence__binary__knn__aggregated__hc__emognition_features_w60_o30 | B7: physiological_features | C7: valence | D7: binary | E7: knn__aggregated__hc__emognition_features_w60_o30 | F7: 5 | G7: emognition_features_w60_o30 | H7: aggregated | I7: hc | J7: knn | K7: trial | L7: 10 | M7: 304 | N7: 42 | O7: 42 | P7: TRUE | Q7: subject_class_macro_recall | R7: 0.52210193 | S7: 42 | T7: 0 | U7: {"{\"clf__n_neighbors\": 3, \"clf__p\": 2, \"clf__weights\": \"uniform\"}": 16, "{\"clf__n_neighbors\": 5, \"clf__p\": 2, \"clf__weights\": \"distance\"}": 5, "{\"clf__n_neighbors\": 5, \"clf__p\": 2, \"clf__weights\": \"uniform\"}": 10, "{\"clf__n_neighbors\": 9, \"clf__p\": 2, \"clf__weights\": \"distance\"}": 2, "{\"clf__n_neighbors\": 9, \"clf__p\": 2, \"clf__weights\": \"uniform\"}": 9} | V7: {"clf__n_neighbors": 3, "clf__p": 2, "clf__weights": "uniform"} | W7: 0.38095238 | X7: FALSE | Y7: 5.3781355 | Z7: 0.3569295 | AA7: 958.74227 | AB7: 304 | AC7: 2 | AD7: 0.51315789 | AE7: 0.51324042 | AF7: 0.51315789 | AG7: 0.51324042 | AH7: 0.51239813 | AI7: 0.026398184 | AJ7: [[72, 68], [80, 84]] | AK7: 0.52182056 | AL7: 0.55200206 | AM7: 140 | AN7: 0.47368421 | AO7: 0.51428571 | AP7: 0.49315068 | AQ7: 164 | AR7: 0.55263158 | AS7: 0.51219512 | AT7: 0.53164557 | AU7: 72 | AV7: 68 | AW7: 80 | AX7: 84 | AY7: 1000 | AZ7: 0.45832661 | BA7: 0.56903527 | BB7: 0.4585588 | BC7: 0.57071247 | BD7: 0.45796289 | BE7: 0.56818583 | BF7: -0.082755852 | BG7: 0.14019178 | BH7: 1000 | BI7: 0.46420559 | BJ7: 0.58170839 | BK7: 6
A8: nested__physiological_features__valence__binary__knn__aggregated__nvg__emognition_features_w60_o30 | B8: physiological_features | C8: valence | D8: binary | E8: knn__aggregated__nvg__emognition_features_w60_o30 | F8: 6 | G8: emognition_features_w60_o30 | H8: aggregated | I8: nvg | J8: knn | K8: trial | L8: 10 | M8: 304 | N8: 42 | O8: 42 | P8: TRUE | Q8: subject_class_macro_recall | R8: 0.55079918 | S8: 42 | T8: 0 | U8: {"{\"clf__n_neighbors\": 3, \"clf__p\": 2, \"clf__weights\": \"uniform\"}": 13, "{\"clf__n_neighbors\": 5, \"clf__p\": 2, \"clf__weights\": \"uniform\"}": 5, "{\"clf__n_neighbors\": 9, \"clf__p\": 2, \"clf__weights\": \"distance\"}": 5, "{\"clf__n_neighbors\": 9, \"clf__p\": 2, \"clf__weights\": \"uniform\"}": 19} | V8: {"clf__n_neighbors": 9, "clf__p": 2, "clf__weights": "uniform"} | W8: 0.45238095 | X8: FALSE | Y8: 5.9101733 | Z8: 0.4104115 | AA8: 1017.3347 | AB8: 304 | AC8: 2 | AD8: 0.54934211 | AE8: 0.54991289 | AF8: 0.54960395 | AG8: 0.54991289 | AH8: 0.54875129 | AI8: 0.09951636 | AJ8: [[78, 62], [75, 89]] | AK8: 0.54394599 | AL8: 0.56112358 | AM8: 140 | AN8: 0.50980392 | AO8: 0.55714286 | AP8: 0.53242321 | AQ8: 164 | AR8: 0.58940397 | AS8: 0.54268293 | AT8: 0.56507937 | AU8: 78 | AV8: 62 | AW8: 75 | AX8: 89 | AY8: 1000 | AZ8: 0.5 | BA8: 0.59731654 | BB8: 0.49916834 | BC8: 0.59790912 | BD8: 0.49855098 | BE8: 0.59573059 | BF8: -0.0016550065 | BG8: 0.19536697 | BH8: 1000 | BI8: 0.49327279 | BJ8: 0.6001915 | BK8: 1
A9: nested__physiological_features__valence__binary__knn__aggregated__hvg__emognition_features_w60_o30 | B9: physiological_features | C9: valence | D9: binary | E9: knn__aggregated__hvg__emognition_features_w60_o30 | F9: 7 | G9: emognition_features_w60_o30 | H9: aggregated | I9: hvg | J9: knn | K9: trial | L9: 10 | M9: 304 | N9: 42 | O9: 42 | P9: TRUE | Q9: subject_class_macro_recall | R9: 0.53207096 | S9: 42 | T9: 0 | U9: {"{\"clf__n_neighbors\": 3, \"clf__p\": 2, \"clf__weights\": \"uniform\"}": 10, "{\"clf__n_neighbors\": 5, \"clf__p\": 2, \"clf__weights\": \"distance\"}": 1, "{\"clf__n_neighbors\": 5, \"clf__p\": 2, \"clf__weights\": \"uniform\"}": 15, "{\"clf__n_neighbors\": 9, \"clf__p\": 2, \"clf__weights\": \"distance\"}": 3, "{\"clf__n_neighbors\": 9, \"clf__p\": 2, \"clf__weights\": \"uniform\"}": 13} | V9: {"clf__n_neighbors": 5, "clf__p": 2, "clf__weights": "uniform"} | W9: 0.35714286 | X9: FALSE | Y9: 5.8893301 | Z9: 0.3998899 | AA9: 1063.1133 | AB9: 304 | AC9: 2 | AD9: 0.52631579 | AE9: 0.52020906 | AF9: 0.52059659 | AG9: 0.52020906 | AH9: 0.51957858 | AI9: 0.04080381 | AJ9: [[62, 78], [66, 98]] | AK9: 0.51023519 | AL9: 0.53211825 | AM9: 140 | AN9: 0.484375 | AO9: 0.44285714 | AP9: 0.46268657 | AQ9: 164 | AR9: 0.55681818 | AS9: 0.59756098 | AT9: 0.57647059 | AU9: 62 | AV9: 78 | AW9: 66 | AX9: 98 | AY9: 1000 | AZ9: 0.47058824 | BA9: 0.58646613 | BB9: 0.46403936 | BC9: 0.58041073 | BD9: 0.46157706 | BE9: 0.57953966 | BF9: -0.073633345 | BG9: 0.16422468 | BH9: 1000 | BI9: 0.47464486 | BJ9: 0.58992834 | BK9: 4
A10: nested__physiological_features__valence__binary__knn__aggregated__hc+nvg__emognition_features_w60_o30 | B10: physiological_features | C10: valence | D10: binary | E10: knn__aggregated__hc+nvg__emognition_features_w60_o30 | F10: 8 | G10: emognition_features_w60_o30 | H10: aggregated | I10: hc+nvg | J10: knn | K10: trial | L10: 10 | M10: 304 | N10: 42 | O10: 42 | P10: TRUE | Q10: subject_class_macro_recall | R10: 0.5371813 | S10: 42 | T10: 0 | U10: {"{\"clf__n_neighbors\": 3, \"clf__p\": 2, \"clf__weights\": \"uniform\"}": 17, "{\"clf__n_neighbors\": 5, \"clf__p\": 2, \"clf__weights\": \"distance\"}": 1, "{\"clf__n_neighbors\": 5, \"clf__p\": 2, \"clf__weights\": \"uniform\"}": 5, "{\"clf__n_neighbors\": 9, \"clf__p\": 2, \"clf__weights\": \"distance\"}": 4, "{\"clf__n_neighbors\": 9, \"clf__p\": 2, \"clf__weights\": \"uniform\"}": 15} | V10: {"clf__n_neighbors": 3, "clf__p": 2, "clf__weights": "uniform"} | W10: 0.4047619 | X10: FALSE | Y10: 6.8261425 | Z10: 0.4507239 | AA10: 1096.6942 | AB10: 304 | AC10: 2 | AD10: 0.52960526 | AE10: 0.52534843 | AF10: 0.52550953 | AG10: 0.52534843 | AH10: 0.52528529 | AI10: 0.05085771 | AJ10: [[66, 74], [69, 95]] | AK10: 0.52865854 | AL10: 0.55425093 | AM10: 140 | AN10: 0.48888889 | AO10: 0.47142857 | AP10: 0.48 | AQ10: 164 | AR10: 0.56213018 | AS10: 0.57926829 | AT10: 0.57057057 | AU10: 66 | AV10: 74 | AW10: 69 | AX10: 95 | AY10: 1000 | AZ10: 0.48219775 | BA10: 0.57679824 | BB10: 0.47781501 | BC10: 0.57434899 | BD10: 0.47550366 | BE10: 0.57244114 | BF10: -0.04461973 | BG10: 0.1486159 | BH10: 1000 | BI10: 0.48712939 | BJ10: 0.58833121 | BK10: 2
A11: nested__physiological_features__valence__binary__knn__aggregated__hc+hvg__emognition_features_w60_o30 | B11: physiological_features | C11: valence | D11: binary | E11: knn__aggregated__hc+hvg__emognition_features_w60_o30 | F11: 9 | G11: emognition_features_w60_o30 | H11: aggregated | I11: hc+hvg | J11: knn | K11: trial | L11: 10 | M11: 304 | N11: 42 | O11: 42 | P11: TRUE | Q11: subject_class_macro_recall | R11: 0.5305756 | S11: 42 | T11: 0 | U11: {"{\"clf__n_neighbors\": 3, \"clf__p\": 2, \"clf__weights\": \"uniform\"}": 12, "{\"clf__n_neighbors\": 5, \"clf__p\": 2, \"clf__weights\": \"uniform\"}": 7, "{\"clf__n_neighbors\": 9, \"clf__p\": 2, \"clf__weights\": \"distance\"}": 7, "{\"clf__n_neighbors\": 9, \"clf__p\": 2, \"clf__weights\": \"uniform\"}": 16} | V11: {"clf__n_neighbors": 9, "clf__p": 2, "clf__weights": "uniform"} | W11: 0.38095238 | X11: FALSE | Y11: 6.6845981 | Z11: 0.4358893 | AA11: 1130.2686 | AB11: 304 | AC11: 2 | AD11: 0.53947368 | AE11: 0.53188153 | AF11: 0.53296703 | AG11: 0.53188153 | AH11: 0.53051229 | AI11: 0.06483948 | AJ11: [[61, 79], [61, 103]] | AK11: 0.4918554 | AL11: 0.5230238 | AM11: 140 | AN11: 0.5 | AO11: 0.43571429 | AP11: 0.46564885 | AQ11: 164 | AR11: 0.56593407 | AS11: 0.62804878 | AT11: 0.59537572 | AU11: 61 | AV11: 79 | AW11: 61 | AX11: 103 | AY11: 1000 | AZ11: 0.49009512 | BA11: 0.58363048 | BB11: 0.48203964 | BC11: 0.5788398 | BD11: 0.4788073 | BE11: 0.57755691 | BF11: -0.036587434 | BG11: 0.15984676 | BH11: 1000 | BI11: 0.47714994 | BJ11: 0.58572421 | BK11: 5
A12: nested__physiological_features__arousal__binary__knn__windowed__hc__emognition_features_w60_o30 | B12: physiological_features | C12: arousal | D12: binary | E12: knn__windowed__hc__emognition_features_w60_o30 | F12: 0 | G12: emognition_features_w60_o30 | H12: windowed | I12: hc | J12: knn | K12: trial | L12: 10 | M12: 278 | N12: 42 | O12: 42 | P12: TRUE | Q12: subject_class_macro_recall | R12: 0.4520393 | S12: 42 | T12: 0 | U12: {"{\"clf__n_neighbors\": 3, \"clf__p\": 2, \"clf__weights\": \"distance\"}": 5, "{\"clf__n_neighbors\": 3, \"clf__p\": 2, \"clf__weights\": \"uniform\"}": 6, "{\"clf__n_neighbors\": 5, \"clf__p\": 2, \"clf__weights\": \"distance\"}": 4, "{\"clf__n_neighbors\": 5, \"clf__p\": 2, \"clf__weights\": \"uniform\"}": 13, "{\"clf__n_neighbors\": 9, \"clf__p\": 2, \"clf__weights\": \"distance\"}": 5, "{\"clf__n_neighbors\": 9, \"clf__p\": 2, \"clf__weights\": \"uniform\"}": 9} | V12: {"clf__n_neighbors": 5, "clf__p": 2, "clf__weights": "uniform"} | W12: 0.30952381 | X12: FALSE | Y12: 5.7497002 | Z12: 0.3458423 | AA12: 652.25573 | AB12: 278 | AC12: 2 | AD12: 0.4028777 | AE12: 0.39276216 | AF12: 0.38836111 | AG12: 0.39276216 | AH12: 0.38893008 | AI12: -0.21883248 | AJ12: [[77, 74], [92, 35]] | AK12: 0.36522918 | AL12: 0.37354665 | AM12: 151 | AN12: 0.4556213 | AO12: 0.50993377 | AP12: 0.48125 | AQ12: 127 | AR12: 0.32110092 | AS12: 0.27559055 | AT12: 0.29661017 | AU12: 77 | AV12: 74 | AW12: 92 | AX12: 35 | AY12: 1000 | AZ12: 0.33695652 | BA12: 0.46935099 | BB12: 0.33675323 | BC12: 0.45783275 | BD12: 0.32557037 | BE12: 0.45300427 | BF12: -0.33639613 | BG12: -0.086203537 | BH12: 1000 | BI12: 0.37667745 | BJ12: 0.52188941 | BK12: 9
A13: nested__physiological_features__arousal__binary__knn__windowed__nvg__emognition_features_w60_o30 | B13: physiological_features | C13: arousal | D13: binary | E13: knn__windowed__nvg__emognition_features_w60_o30 | F13: 1 | G13: emognition_features_w60_o30 | H13: windowed | I13: nvg | J13: knn | K13: trial | L13: 10 | M13: 278 | N13: 42 | O13: 42 | P13: TRUE | Q13: subject_class_macro_recall | R13: 0.4557423 | S13: 42 | T13: 0 | U13: {"{\"clf__n_neighbors\": 3, \"clf__p\": 2, \"clf__weights\": \"distance\"}": 1, "{\"clf__n_neighbors\": 3, \"clf__p\": 2, \"clf__weights\": \"uniform\"}": 12, "{\"clf__n_neighbors\": 5, \"clf__p\": 2, \"clf__weights\": \"uniform\"}": 8, "{\"clf__n_neighbors\": 9, \"clf__p\": 2, \"clf__weights\": \"distance\"}": 3, "{\"clf__n_neighbors\": 9, \"clf__p\": 2, \"clf__weights\": \"uniform\"}": 18} | V13: {"clf__n_neighbors": 9, "clf__p": 2, "clf__weights": "uniform"} | W13: 0.42857143 | X13: FALSE | Y13: 5.9776625 | Z13: 0.3754534 | AA13: 706.57729 | AB13: 278 | AC13: 2 | AD13: 0.4676259 | AE13: 0.45674506 | AF13: 0.45433526 | AG13: 0.45674506 | AH13: 0.45263942 | AI13: -0.088887021 | AJ13: [[88, 63], [85, 42]] | AK13: 0.43158471 | AL13: 0.41139422 | AM13: 151 | AN13: 0.50867052 | AO13: 0.58278146 | AP13: 0.54320988 | AQ13: 127 | AR13: 0.4 | AS13: 0.33070866 | AT13: 0.36206897 | AU13: 88 | AV13: 63 | AW13: 85 | AX13: 42 | AY13: 1000 | AZ13: 0.39923097 | BA13: 0.53003633 | BB13: 0.39902612 | BC13: 0.5162469 | BD13: 0.39308124 | BE13: 0.50996319 | BF13: -0.20253313 | BG13: 0.033156559 | BH13: 1000 | BI13: 0.39564786 | BJ13: 0.5166176 | BK13: 8
... A21: nested__physiological_features__arousal__binary__knn__aggregated__hc+hvg__emognition_features_w60_o30 | B21: physiological_features | C21: arousal | D21: binary | E21: knn__aggregated__hc+hvg__emognition_features_w60_o30 | F21: 9 | G21: emognition_features_w60_o30 | H21: aggregated | I21: hc+hvg | J21: knn | K21: trial | L21: 10 | M21: 278 | N21: 42 | O21: 42 | P21: TRUE | Q21: subject_class_macro_recall | R21: 0.44811932 | S21: 42 | T21: 0 | U21: {"{\"clf__n_neighbors\": 3, \"clf__p\": 2, \"clf__weights\": \"uniform\"}": 8, "{\"clf__n_neighbors\": 5, \"clf__p\": 2, \"clf__weights\": \"uniform\"}": 10, "{\"clf__n_neighbors\": 9, \"clf__p\": 2, \"clf__weights\": \"uniform\"}": 24} | V21: {"clf__n_neighbors": 9, "clf__p": 2, "clf__weights": "uniform"} | W21: 0.57142857 | X21: FALSE | Y21: 6.872251 | Z21: 0.4034305 | AA21: 1083.1528 | AB21: 278 | AC21: 2 | AD21: 0.43884892 | AE21: 0.43150649 | AF21: 0.43027021 | AG21: 0.43150649 | AH21: 0.43032787 | AI21: -0.13821777 | AJ21: [[78, 73], [83, 44]] | AK21: 0.41325546 | AL21: 0.40824701 | AM21: 151 | AN21: 0.48447205 | AO21: 0.51655629 | AP21: 0.5 | AQ21: 127 | AR21: 0.37606838 | AS21: 0.34645669 | AT21: 0.36065574 | AU21: 78 | AV21: 73 | AW21: 83 | AX21: 44 | AY21: 1000 | AZ21: 0.36968588 | BA21: 0.51592175 | BB21: 0.36737849 | BC21: 0.50351777 | BD21: 0.36550758 | BE21: 0.49986937 | BF21: -0.26456579 | BG21: 0.0072087992 | BH21: 1000 | BI21: 0.36884781 | BJ21: 0.53086717 | BK21: 10
A22: nested__physiological_features__valence__ternary__knn__windowed__hc__emognition_features_w60_o30 | B22: physiological_features | C22: valence | D22: ternary | E22: knn__windowed__hc__emognition_features_w60_o30 | F22: 0 | G22: emognition_features_w60_o30 | H22: windowed | I22: hc | J22: knn | K22: trial | L22: 10 | M22: 332 | N22: 42 | O22: 42 | P22: TRUE | Q22: subject_class_macro_recall | R22: 0.32506062 | S22: 42 | T22: 0 | U22: {"{\"clf__n_neighbors\": 3, \"clf__p\": 2, \"clf__weights\": \"distance\"}": 4, "{\"clf__n_neighbors\": 3, \"clf__p\": 2, \"clf__weights\": \"uniform\"}": 5, "{\"clf__n_neighbors\": 5, \"clf__p\": 2, \"clf__weights\": \"distance\"}": 4, "{\"clf__n_neighbors\": 5, \"clf__p\": 2, \"clf__weights\": \"uniform\"}": 7, "{\"clf__n_neighbors\": 9, \"clf__p\": 2, \"clf__weights\": \"distance\"}": 7, "{\"clf__n_neighbors\": 9, \"clf__p\": 2, \"clf__weights\": \"uniform\"}": 15} | V22: {"clf__n_neighbors": 9, "clf__p": 2, "clf__weights": "uniform"} | W22: 0.35714286 | X22: FALSE | Y22: 6.089033 | Z22: 0.3670491 | AA22: 789.78713 | AB22: 332 | AC22: 3 | AD22: 0.3373494 | AE22: 0.33821923 | AF22: 0.33752635 | AG22: 0.33821923 | AH22: 0.33708255 | AI22: 0.0064219687 | AJ22: [[39, 30, 35], [37, 34, 38], [43, 37, 39]] | AK22: 0.47766654 | AM22: 104 | AN22: 0.32773109 | AO22: 0.375 | AP22: 0.34977578 | AQ22: 109 | AR22: 0.33663366 | AS22: 0.31192661 | AT22: 0.32380952 | AU22: 119 | AV22: 0.34821429 | AW22: 0.32773109 | AX22: 0.33766234 | AY22: 1000 | AZ22: 0.29214674 | BA22: 0.38555407 | BB22: 0.29332931 | BC22: 0.38763067 | BD22: 0.28959313 | BE22: 0.38403644 | BF22: -0.061390886 | BG22: 0.078728463 | BH22: 1000 | BI22: 0.27767589 | BJ22: 0.37417893 | BK22: 8
A23: nested__physiological_features__valence__ternary__knn__windowed__nvg__emognition_features_w60_o30 | B23: physiological_features | C23: valence | D23: ternary | E23: knn__windowed__nvg__emognition_features_w60_o30 | F23: 1 | G23: emognition_features_w60_o30 | H23: windowed | I23: nvg | J23: knn | K23: trial | L23: 10 | M23: 332 | N23: 42 | O23: 42 | P23: TRUE | Q23: subject_class_macro_recall | R23: 0.36869206 | S23: 42 | T23: 0 | U23: {"{\"clf__n_neighbors\": 3, \"clf__p\": 2, \"clf__weights\": \"distance\"}": 2, "{\"clf__n_neighbors\": 3, \"clf__p\": 2, \"clf__weights\": \"uniform\"}": 7, "{\"clf__n_neighbors\": 5, \"clf__p\": 2, \"clf__weights\": \"distance\"}": 4, "{\"clf__n_neighbors\": 5, \"clf__p\": 2, \"clf__weights\": \"uniform\"}": 8, "{\"clf__n_neighbors\": 9, \"clf__p\": 2, \"clf__weights\": \"distance\"}": 9, "{\"clf__n_neighbors\": 9, \"clf__p\": 2, \"clf__weights\": \"uniform\"}": 12} | V23: {"clf__n_neighbors": 9, "clf__p": 2, "clf__weights": "uniform"} | W23: 0.28571429 | X23: FALSE | Y23: 6.3240773 | Z23: 0.4094219 | AA23: 820.95682 | AB23: 332 | AC23: 3 | AD23: 0.35542169 | AE23: 0.35631211 | AF23: 0.35163422 | AG23: 0.35631211 | AH23: 0.35256709 | AI23: 0.032311602 | AJ23: [[46, 26, 32], [35, 28, 46], [38, 37, 44]] | AK23: 0.51153269 | AM23: 104 | AN23: 0.38655462 | AO23: 0.44230769 | AP23: 0.41255605 | AQ23: 109 | AR23: 0.30769231 | AS23: 0.25688073 | AT23: 0.28 | AU23: 119 | AV23: 0.36065574 | AW23: 0.3697479 | AX23: 0.36514523 | AY23: 1000 | AZ23: 0.30421687 | BA23: 0.40419321 | BB23: 0.30434933 | BC23: 0.40907189 | BD23: 0.30162668 | BE23: 0.40134866 | BF23: -0.043696761 | BG23: 0.10735291 | BH23: 1000 | BI23: 0.31639792 | BJ23: 0.42344719 | BK23: 3
A24: nested__physiological_features__valence__ternary__knn__windowed__hvg__emognition_features_w60_o30 | B24: physiological_features | C24: valence | D24: ternary | E24: knn__windowed__hvg__emognition_features_w60_o30 | F24: 2 | G24: emognition_features_w60_o30 | H24: windowed | I24: hvg | J24: knn | K24: trial | L24: 10 | M24: 332 | N24: 42 | O24: 42 | P24: TRUE | Q24: subject_class_macro_recall | R24: 0.30288832 | S24: 42 | T24: 0 | U24: {"{\"clf__n_neighbors\": 3, \"clf__p\": 2, \"clf__weights\": \"distance\"}": 4, "{\"clf__n_neighbors\": 3, \"clf__p\": 2, \"clf__weights\": \"uniform\"}": 13, "{\"clf__n_neighbors\": 5, \"clf__p\": 2, \"clf__weights\": \"distance\"}": 10, "{\"clf__n_neighbors\": 5, \"clf__p\": 2, \"clf__weights\": \"uniform\"}": 5, "{\"clf__n_neighbors\": 9, \"clf__p\": 2, \"clf__weights\": \"distance\"}": 5, "{\"clf__n_neighbors\": 9, \"clf__p\": 2, \"clf__weights\": \"uniform\"}": 5} | V24: {"clf__n_neighbors": 3, "clf__p": 2, "clf__weights": "uniform"} | W24: 0.30952381 | X24: FALSE | Y24: 6.2368776 | Z24: 0.4521312 | AA24: 852.07402 | AB24: 332 | AC24: 3 | AD24: 0.33433735 | AE24: 0.33237014 | AF24: 0.33394173 | AG24: 0.33237014 | AH24: 0.3315981 | AI24: 0.00026004106 | AJ24: [[34, 32, 38], [40, 30, 39], [45, 27, 47]] | AK24: 0.48917694 | AM24: 104 | AN24: 0.28571429 | AO24: 0.32692308 | AP24: 0.30493274 | AQ24: 109 | AR24: 0.33707865 | AS24: 0.27522936 | AT24: 0.3030303 | AU24: 119 | AV24: 0.37903226 | AW24: 0.39495798 | AX24: 0.38683128 | AY24: 1000 | AZ24: 0.28828829 | BA24: 0.38323353 | BB24: 0.28684845 | BC24: 0.37997642 | BD24: 0.28371606 | BE24: 0.37744156 | BF24: -0.069865299 | BG24: 0.071645845 | BH24: 1000 | BI24: 0.25648583 | BJ24: 0.35140425 | BK24: 10
A25: nested__physiological_features__valence__ternary__knn__windowed__hc+nvg__emognition_features_w60_o30 | B25: physiological_features | C25: valence | D25: ternary | E25: knn__windowed__hc+nvg__emognition_features_w60_o30 | F25: 3 | G25: emognition_features_w60_o30 | H25: windowed | I25: hc+nvg | J25: knn | K25: trial | L25: 10 | M25: 332 | N25: 42 | O25: 42 | P25: TRUE | Q25: subject_class_macro_recall | R25: 0.34052204 | S25: 42 | T25: 0 | U25: {"{\"clf__n_neighbors\": 3, \"clf__p\": 2, \"clf__weights\": \"distance\"}": 6, "{\"clf__n_neighbors\": 3, \"clf__p\": 2, \"clf__weights\": \"uniform\"}": 6, "{\"clf__n_neighbors\": 5, \"clf__p\": 2, \"clf__weights\": \"distance\"}": 5, "{\"clf__n_neighbors\": 5, \"clf__p\": 2, \"clf__weights\": \"uniform\"}": 9, "{\"clf__n_neighbors\": 9, \"clf__p\": 2, \"clf__weights\": \"distance\"}": 9, "{\"clf__n_neighbors\": 9, \"clf__p\": 2, \"clf__weights\": \"uniform\"}": 7} | V25: {"clf__n_neighbors": 9, "clf__p": 2, "clf__weights": "distance"} | W25: 0.21428571 | X25: FALSE | Y25: 7.1521495 | Z25: 0.4918326 | AA25: 883.27658 | AB25: 332 | AC25: 3 | AD25: 0.34939759 | AE25: 0.35137086 | AF25: 0.34645861 | AG25: 0.35137086 | AH25: 0.34670907 | AI25: 0.025356419 | AJ25: [[47, 25, 32], [41, 29, 39], [40, 39, 40]] | AK25: 0.51881126 | AM25: 104 | AN25: 0.3671875 | AO25: 0.45192308 | AP25: 0.40517241 | AQ25: 109 | AR25: 0.31182796 | AS25: 0.26605505 | AT25: 0.28712871 | AU25: 119 | AV25: 0.36036036 | AW25: 0.33613445 | AX25: 0.34782609 | AY25: 1000 | AZ25: 0.30027782 | BA25: 0.40425249 | BB25: 0.30108329 | BC25: 0.40761886 | BD25: 0.29531432 | BE25: 0.40098387 | BF25: -0.048968226 | BG25: 0.11008712 | BH25: 1000 | BI25: 0.29766942 | BJ25: 0.38825199 | BK25: 7
A26: nested__physiological_features__valence__ternary__knn__windowed__hc+hvg__emognition_features_w60_o30 | B26: physiological_features | C26: valence | D26: ternary | E26: knn__windowed__hc+hvg__emognition_features_w60_o30 | F26: 4 | G26: emognition_features_w60_o30 | H26: windowed | I26: hc+hvg | J26: knn | K26: trial | L26: 10 | M26: 332 | N26: 42 | O26: 42 | P26: TRUE | Q26: subject_class_macro_recall | R26: 0.30645771 | S26: 42 | T26: 0 | U26: {"{\"clf__n_neighbors\": 3, \"clf__p\": 2, \"clf__weights\": \"distance\"}": 13, "{\"clf__n_neighbors\": 3, \"clf__p\": 2, \"clf__weights\": \"uniform\"}": 3, "{\"clf__n_neighbors\": 5, \"clf__p\": 2, \"clf__weights\": \"distance\"}": 6, "{\"clf__n_neighbors\": 5, \"clf__p\": 2, \"clf__weights\": \"uniform\"}": 7, "{\"clf__n_neighbors\": 9, \"clf__p\": 2, \"clf__weights\": \"distance\"}": 4, "{\"clf__n_neighbors\": 9, \"clf__p\": 2, \"clf__weights\": \"uniform\"}": 9} | V26: {"clf__n_neighbors": 3, "clf__p": 2, "clf__weights": "distance"} | W26: 0.30952381 | X26: FALSE | Y26: 7.124156 | Z26: 0.5165796 | AA26: 914.38923 | AB26: 332 | AC26: 3 | AD26: 0.32228916 | AE26: 0.31984367 | AF26: 0.32304987 | AG26: 0.31984367 | AH26: 0.31872974 | AI26: -0.018950227 | AJ26: [[32, 28, 44], [41, 28, 40], [46, 26, 47]] | AK26: 0.49073338 | AM26: 104 | AN26: 0.26890756 | AO26: 0.30769231 | AP26: 0.28699552 | AQ26: 109 | AR26: 0.34146341 | AS26: 0.25688073 | AT26: 0.29319372 | AU26: 119 | AV26: 0.35877863 | AW26: 0.39495798 | AX26: 0.376 | AY26: 1000 | AZ26: 0.26888218 | BA26: 0.37951807 | BB26: 0.26487207 | BC26: 0.37768077 | BD26: 0.2629043 | BE26: 0.37554921 | BF26: -0.10028208 | BG26: 0.066966725 | BH26: 1000 | BI26: 0.25029522 | BJ26: 0.36499276 | BK26: 9
A27: nested__physiological_features__valence__ternary__knn__aggregated__hc__emognition_features_w60_o30 | B27: physiological_features | C27: valence | D27: ternary | E27: knn__aggregated__hc__emognition_features_w60_o30 | F27: 5 | G27: emognition_features_w60_o30 | H27: aggregated | I27: hc | J27: knn | K27: trial | L27: 10 | M27: 332 | N27: 42 | O27: 42 | P27: TRUE | Q27: subject_class_macro_recall | R27: 0.34930466 | S27: 42 | T27: 0 | U27: {"{\"clf__n_neighbors\": 3, \"clf__p\": 2, \"clf__weights\": \"distance\"}": 6, "{\"clf__n_neighbors\": 3, \"clf__p\": 2, \"clf__weights\": \"uniform\"}": 14, "{\"clf__n_neighbors\": 5, \"clf__p\": 2, \"clf__weights\": \"distance\"}": 2, "{\"clf__n_neighbors\": 5, \"clf__p\": 2, \"clf__weights\": \"uniform\"}": 9, "{\"clf__n_neighbors\": 9, \"clf__p\": 2, \"clf__weights\": \"distance\"}": 5, "{\"clf__n_neighbors\": 9, \"clf__p\": 2, \"clf__weights\": \"uniform\"}": 6} | V27: {"clf__n_neighbors": 3, "clf__p": 2, "clf__weights": "uniform"} | W27: 0.33333333 | X27: FALSE | Y27: 5.6015343 | Z27: 0.3831171 | AA27: 945.54036 | AB27: 332 | AC27: 3 | AD27: 0.3313253 | AE27: 0.33302224 | AF27: 0.32743884 | AG27: 0.33302224 | AH27: 0.32570391 | AI27: -4.1288993e-05 | AJ27: [[47, 26, 31], [53, 23, 33], [41, 38, 40]] | AK27: 0.48675127 | AM27: 104 | AN27: 0.33333333 | AO27: 0.45192308 | AP27: 0.38367347 | AQ27: 109 | AR27: 0.26436782 | AS27: 0.21100917 | AT27: 0.23469388 | AU27: 119 | AV27: 0.38461538 | AW27: 0.33613445 | AX27: 0.35874439 | AY27: 1000 | AZ27: 0.27658776 | BA27: 0.38922156 | BB27: 0.28223499 | BC27: 0.39020774 | BD27: 0.27034218 | BE27: 0.3825495 | BF27: -0.080506956 | BG27: 0.086999536 | BH27: 1000 | BI27: 0.28879516 | BJ27: 0.41382242 | BK27: 5
A28: nested__physiological_features__valence__ternary__knn__aggregated__nvg__emognition_features_w60_o30 | B28: physiological_features | C28: valence | D28: ternary | E28: knn__aggregated__nvg__emognition_features_w60_o30 | F28: 6 | G28: emognition_features_w60_o30 | H28: aggregated | I28: nvg | J28: knn | K28: trial | L28: 10 | M28: 332 | N28: 42 | O28: 42 | P28: TRUE | Q28: subject_class_macro_recall | R28: 0.393635 | S28: 42 | T28: 0 | U28: {"{\"clf__n_neighbors\": 3, \"clf__p\": 2, \"clf__weights\": \"distance\"}": 10, "{\"clf__n_neighbors\": 3, \"clf__p\": 2, \"clf__weights\": \"uniform\"}": 6, "{\"clf__n_neighbors\": 5, \"clf__p\": 2, \"clf__weights\": \"distance\"}": 14, "{\"clf__n_neighbors\": 5, \"clf__p\": 2, \"clf__weights\": \"uniform\"}": 2, "{\"clf__n_neighbors\": 9, \"clf__p\": 2, \"clf__weights\": \"distance\"}": 6, "{\"clf__n_neighbors\": 9, \"clf__p\": 2, \"clf__weights\": \"uniform\"}": 4} | V28: {"clf__n_neighbors": 5, "clf__p": 2, "clf__weights": "distance"} | W28: 0.33333333 | X28: FALSE | Y28: 6.1176951 | Z28: 0.4194299 | AA28: 977.12563 | AB28: 332 | AC28: 3 | AD28: 0.36746988 | AE28: 0.37089444 | AF28: 0.36945874 | AG28: 0.37089444 | AH28: 0.36628571 | AI28: 0.055600225 | AJ28: [[48, 30, 26], [43, 38, 28], [38, 45, 36]] | AK28: 0.53942858 | AM28: 104 | AN28: 0.37209302 | AO28: 0.46153846 | AP28: 0.41201717 | AQ28: 109 | AR28: 0.33628319 | AS28: 0.34862385 | AT28: 0.34234234 | AU28: 119 | AV28: 0.4 | AW28: 0.30252101 | AX28: 0.34449761 | AY28: 1000 | AZ28: 0.32634731 | BA28: 0.41141576 | BB28: 0.32882086 | BC28: 0.41499373 | BD28: 0.32483491 | BE28: 0.40916358 | BF28: -0.0063396108 | BG28: 0.12024103 | BH28: 1000 | BI28: 0.33981779 | BJ28: 0.45276476 | BK28: 1
A29: nested__physiological_features__valence__ternary__knn__aggregated__hvg__emognition_features_w60_o30 | B29: physiological_features | C29: valence | D29: ternary | E29: knn__aggregated__hvg__emognition_features_w60_o30 | F29: 7 | G29: emognition_features_w60_o30 | H29: aggregated | I29: hvg | J29: knn | K29: trial | L29: 10 | M29: 332 | N29: 42 | O29: 42 | P29: TRUE | Q29: subject_class_macro_recall | R29: 0.37256811 | S29: 42 | T29: 0 | U29: {"{\"clf__n_neighbors\": 3, \"clf__p\": 2, \"clf__weights\": \"distance\"}": 1, "{\"clf__n_neighbors\": 3, \"clf__p\": 2, \"clf__weights\": \"uniform\"}": 3, "{\"clf__n_neighbors\": 5, \"clf__p\": 2, \"clf__weights\": \"distance\"}": 3, "{\"clf__n_neighbors\": 5, \"clf__p\": 2, \"clf__weights\": \"uniform\"}": 15, "{\"clf__n_neighbors\": 9, \"clf__p\": 2, \"clf__weights\": \"distance\"}": 4, "{\"clf__n_neighbors\": 9, \"clf__p\": 2, \"clf__weights\": \"uniform\"}": 16} | V29: {"clf__n_neighbors": 9, "clf__p": 2, "clf__weights": "uniform"} | W29: 0.38095238 | X29: FALSE | Y29: 6.2641772 | Z29: 0.411681 | AA29: 1033.2888 | AB29: 332 | AC29: 3 | AD29: 0.37650602 | AE29: 0.37478206 | AF29: 0.3677243 | AG29: 0.37478206 | AH29: 0.36571511 | AI29: 0.066169148 | AJ29: [[47, 29, 28], [50, 22, 37], [40, 23, 56]] | AK29: 0.50870652 | AM29: 104 | AN29: 0.34306569 | AO29: 0.45192308 | AP29: 0.39004149 | AQ29: 109 | AR29: 0.2972973 | AS29: 0.20183486 | AT29: 0.24043716 | AU29: 119 | AV29: 0.46280992 | AW29: 0.47058824 | AX29: 0.46666667 | AY29: 1000 | AZ29: 0.32831325 | BA29: 0.43296992 | BB29: 0.32901997 | BC29: 0.42643721 | BD29: 0.31948206 | BE29: 0.4167237 | BF29: -0.0029794856 | BG29: 0.14750752 | BH29: 1000 | BI29: 0.31816911 | BJ29: 0.43193709 | BK29: 2
A30: nested__physiological_features__valence__ternary__knn__aggregated__hc+nvg__emognition_features_w60_o30 | B30: physiological_features | C30: valence | D30: ternary | E30: knn__aggregated__hc+nvg__emognition_features_w60_o30 | F30: 8 | G30: emognition_features_w60_o30 | H30: aggregated | I30: hc+nvg | J30: knn | K30: trial | L30: 10 | M30: 332 | N30: 42 | O30: 42 | P30: TRUE | Q30: subject_class_macro_recall | R30: 0.35591927 | S30: 42 | T30: 0 | U30: {"{\"clf__n_neighbors\": 3, \"clf__p\": 2, \"clf__weights\": \"distance\"}": 14, "{\"clf__n_neighbors\": 3, \"clf__p\": 2, \"clf__weights\": \"uniform\"}": 7, "{\"clf__n_neighbors\": 5, \"clf__p\": 2, \"clf__weights\": \"distance\"}": 3, "{\"clf__n_neighbors\": 5, \"clf__p\": 2, \"clf__weights\": \"uniform\"}": 6, "{\"clf__n_neighbors\": 9, \"clf__p\": 2, \"clf__weights\": \"distance\"}": 5, "{\"clf__n_neighbors\": 9, \"clf__p\": 2, \"clf__weights\": \"uniform\"}": 7} | V30: {"clf__n_neighbors": 3, "clf__p": 2, "clf__weights": "distance"} | W30: 0.33333333 | X30: FALSE | Y30: 6.9608703 | Z30: 0.4852136 | AA30: 1099.9665 | AB30: 332 | AC30: 3 | AD30: 0.35240964 | AE30: 0.35369508 | AF30: 0.34836661 | AG30: 0.35369508 | AH30: 0.34518896 | AI30: 0.030343113 | AJ30: [[49, 19, 36], [49, 24, 36], [42, 33, 44]] | AK30: 0.50502576 | AM30: 104 | AN30: 0.35 | AO30: 0.47115385 | AP30: 0.40163934 | AQ30: 109 | AR30: 0.31578947 | AS30: 0.22018349 | AT30: 0.25945946 | AU30: 119 | AV30: 0.37931034 | AW30: 0.3697479 | AX30: 0.37446809 | AY30: 1000 | AZ30: 0.30118221 | BA30: 0.40062673 | BB30: 0.30518496 | BC30: 0.40398614 | BD30: 0.29445882 | BE30: 0.39236218 | BF30: -0.043287623 | BG30: 0.10567477 | BH30: 1000 | BI30: 0.30266139 | BJ30: 0.40582517 | BK30: 4
A31: nested__physiological_features__valence__ternary__knn__aggregated__hc+hvg__emognition_features_w60_o30 | B31: physiological_features | C31: valence | D31: ternary | E31: knn__aggregated__hc+hvg__emognition_features_w60_o30 | F31: 9 | G31: emognition_features_w60_o30 | H31: aggregated | I31: hc+hvg | J31: knn | K31: trial | L31: 10 | M31: 332 | N31: 42 | O31: 42 | P31: TRUE | Q31: subject_class_macro_recall | R31: 0.34502567 | S31: 42 | T31: 0 | U31: {"{\"clf__n_neighbors\": 3, \"clf__p\": 2, \"clf__weights\": \"distance\"}": 12, "{\"clf__n_neighbors\": 3, \"clf__p\": 2, \"clf__weights\": \"uniform\"}": 3, "{\"clf__n_neighbors\": 5, \"clf__p\": 2, \"clf__weights\": \"distance\"}": 9, "{\"clf__n_neighbors\": 5, \"clf__p\": 2, \"clf__weights\": \"uniform\"}": 8, "{\"clf__n_neighbors\": 9, \"clf__p\": 2, \"clf__weights\": \"distance\"}": 8, "{\"clf__n_neighbors\": 9, \"clf__p\": 2, \"clf__weights\": \"uniform\"}": 2} | V31: {"clf__n_neighbors": 3, "clf__p": 2, "clf__weights": "distance"} | W31: 0.28571429 | X31: FALSE | Y31: 7.0531836 | Z31: 0.4693104 | AA31: 1165.1574 | AB31: 332 | AC31: 3 | AD31: 0.35240964 | AE31: 0.35218901 | AF31: 0.34754606 | AG31: 0.35218901 | AH31: 0.34751257 | AI31: 0.02784912 | AJ31: [[44, 28, 32], [38, 26, 45], [41, 31, 47]] | AK31: 0.52385009 | AM31: 104 | AN31: 0.35772358 | AO31: 0.42307692 | AP31: 0.3876652 | AQ31: 109 | AR31: 0.30588235 | AS31: 0.23853211 | AT31: 0.26804124 | AU31: 119 | AV31: 0.37903226 | AW31: 0.39495798 | AX31: 0.38683128 | AY31: 1000 | AZ31: 0.30118221 | BA31: 0.3993994 | BB31: 0.30015198 | BC31: 0.40179857 | BD31: 0.29694918 | BE31: 0.39477073 | BF31: -0.047816579 | BG31: 0.10085433 | BH31: 1000 | BI31: 0.29244707 | BJ31: 0.39729047 | BK31: 6
A32: nested__physiological_features__arousal__ternary__knn__windowed__hc__emognition_features_w60_o30 | B32: physiological_features | C32: arousal | D32: ternary | E32: knn__windowed__hc__emognition_features_w60_o30 | F32: 0 | G32: emognition_features_w60_o30 | H32: windowed | I32: hc | J32: knn | K32: trial | L32: 10 | M32: 332 | N32: 42 | O32: 42 | P32: TRUE | Q32: subject_class_macro_recall | R32: 0.26720805 | S32: 42 | T32: 0 | U32: {"{\"clf__n_neighbors\": 3, \"clf__p\": 2, \"clf__weights\": \"distance\"}": 15, "{\"clf__n_neighbors\": 3, \"clf__p\": 2, \"clf__weights\": \"uniform\"}": 8, "{\"clf__n_neighbors\": 5, \"clf__p\": 2, \"clf__weights\": \"distance\"}": 3, "{\"clf__n_neighbors\": 5, \"clf__p\": 2, \"clf__weights\": \"uniform\"}": 3, "{\"clf__n_neighbors\": 9, \"clf__p\": 2, \"clf__weights\": \"distance\"}": 7, "{\"clf__n_neighbors\": 9, \"clf__p\": 2, \"clf__weights\": \"uniform\"}": 6} | V32: {"clf__n_neighbors": 3, "clf__p": 2, "clf__weights": "distance"} | W32: 0.35714286 | X32: FALSE | Y32: 7.6856038 | Z32: 0.5358705 | AA32: 1187.3375 | AB32: 332 | AC32: 3 | AD32: 0.30120482 | AE32: 0.26198691 | AF32: 0.25058275 | AG32: 0.26198691 | AH32: 0.25400999 | AI32: -0.10904694 | AJ32: [[26, 57, 20], [54, 68, 26], [30, 45, 6]] | AK32: 0.42318604 | AM32: 103 | AN32: 0.23636364 | AO32: 0.25242718 | AP32: 0.24413146 | AQ32: 148 | AR32: 0.4 | AS32: 0.45945946 | AT32: 0.42767296 | AU32: 81 | AV32: 0.11538462 | AW32: 0.074074074 | AX32: 0.090225564 | AY32: 1000 | AZ32: 0.24702291 | BA32: 0.35045317 | BB32: 0.21799114 | BC32: 0.30620591 | BD32: 0.20948228 | BE32: 0.29549338 | BF32: -0.17720061 | BG32: -0.040908368 | BH32: 1000 | BI32: 0.22055927 | BJ32: 0.31498339 | BK32: 10
A33: nested__physiological_features__arousal__ternary__knn__windowed__nvg__emognition_features_w60_o30 | B33: physiological_features | C33: arousal | D33: ternary | E33: knn__windowed__nvg__emognition_features_w60_o30 | F33: 1 | G33: emognition_features_w60_o30 | H33: windowed | I33: nvg | J33: knn | K33: trial | L33: 10 | M33: 332 | N33: 42 | O33: 42 | P33: TRUE | Q33: subject_class_macro_recall | R33: 0.31161662 | S33: 42 | T33: 0 | U33: {"{\"clf__n_neighbors\": 3, \"clf__p\": 2, \"clf__weights\": \"distance\"}": 5, "{\"clf__n_neighbors\": 3, \"clf__p\": 2, \"clf__weights\": \"uniform\"}": 11, "{\"clf__n_neighbors\": 5, \"clf__p\": 2, \"clf__weights\": \"distance\"}": 8, "{\"clf__n_neighbors\": 5, \"clf__p\": 2, \"clf__weights\": \"uniform\"}": 10, "{\"clf__n_neighbors\": 9, \"clf__p\": 2, \"clf__weights\": \"distance\"}": 5, "{\"clf__n_neighbors\": 9, \"clf__p\": 2, \"clf__weights\": \"uniform\"}": 3} | V33: {"clf__n_neighbors": 3, "clf__p": 2, "clf__weights": "uniform"} | W33: 0.26190476 | X33: FALSE | Y33: 8.6198813 | Z33: 0.5445038 | AA33: 1253.9588 | AB33: 332 | AC33: 3 | AD33: 0.38554217 | AE33: 0.33949483 | AF33: 0.3347913 | AG33: 0.33949483 | AH33: 0.33006372 | AI33: 0.010421984 | AJ33: [[35, 56, 12], [40, 84, 24], [21, 51, 9]] | AK33: 0.52351465 | AM33: 103 | AN33: 0.36458333 | AO33: 0.33980583 | AP33: 0.35175879 | AQ33: 148 | AR33: 0.43979058 | AS33: 0.56756757 | AT33: 0.49557522 | AU33: 81 | AV33: 0.2 | AW33: 0.11111111 | AX33: 0.14285714 | AY33: 1000 | AZ33: 0.33130043 | BA33: 0.44012867 | BB33: 0.29252772 | BC33: 0.38724583 | BD33: 0.27979809 | BE33: 0.3762653 | BF33: -0.070081631 | BG33: 0.092533382 | BH33: 1000 | BI33: 0.26476216 | BJ33: 0.36413333 | BK33: 9
... A41: nested__physiological_features__arousal__ternary__knn__aggregated__hc+hvg__emognition_features_w60_o30 | B41: physiological_features | C41: arousal | D41: ternary | E41: knn__aggregated__hc+hvg__emognition_features_w60_o30 | F41: 9 | G41: emognition_features_w60_o30 | H41: aggregated | I41: hc+hvg | J41: knn | K41: trial | L41: 10 | M41: 332 | N41: 42 | O41: 42 | P41: TRUE | Q41: subject_class_macro_recall | R41: 0.36247107 | S41: 42 | T41: 0 | U41: {"{\"clf__n_neighbors\": 3, \"clf__p\": 2, \"clf__weights\": \"distance\"}": 5, "{\"clf__n_neighbors\": 3, \"clf__p\": 2, \"clf__weights\": \"uniform\"}": 12, "{\"clf__n_neighbors\": 5, \"clf__p\": 2, \"clf__weights\": \"distance\"}": 7, "{\"clf__n_neighbors\": 5, \"clf__p\": 2, \"clf__weights\": \"uniform\"}": 11, "{\"clf__n_neighbors\": 9, \"clf__p\": 2, \"clf__weights\": \"distance\"}": 1, "{\"clf__n_neighbors\": 9, \"clf__p\": 2, \"clf__weights\": \"uniform\"}": 6} | V41: {"clf__n_neighbors": 3, "clf__p": 2, "clf__weights": "uniform"} | W41: 0.28571429 | X41: FALSE | Y41: 10.644091 | Z41: 0.642706 | AA41: 1586.6095 | AB41: 332 | AC41: 3 | AD41: 0.39457831 | AE41: 0.35468748 | AF41: 0.35088157 | AG41: 0.35468748 | AH41: 0.35019991 | AI41: 0.042275539 | AJ41: [[36, 47, 20], [41, 82, 25], [27, 41, 13]] | AK41: 0.51790418 | AM41: 103 | AN41: 0.34615385 | AO41: 0.34951456 | AP41: 0.34782609 | AQ41: 148 | AR41: 0.48235294 | AS41: 0.55405405 | AT41: 0.51572327 | AU41: 81 | AV41: 0.22413793 | AW41: 0.16049383 | AX41: 0.18705036 | AY41: 1000 | AZ41: 0.33330838 | BA41: 0.45619993 | BB41: 0.30869936 | BC41: 0.40335201 | BD41: 0.30125246 | BE41: 0.39814795 | BF41: -0.031738596 | BG41: 0.12213551 | BH41: 1000 | BI41: 0.30944053 | BJ41: 0.42091055 | BK41: 1
A42: experiment_id | B42: dataset_id | C42: target | D42: task_kind | E42: candidate_id | F42: candidate_order | G42: input_id | H42: input_mode | I42: representation | J42: model | K42: evaluation_unit | L42: total_candidate_count | M42: common_trial_count | N42: subjects_total | O42: outer_folds_run | P42: complete_loso | Q42: primary_metric | R42: primary_score | S42: primary_evaluable_subjects | T42: primary_excluded_subjects | U42: best_parameter_counts_json | V42: most_frequent_parameters_json | W42: parameter_stability_fraction | X42: quick_grid | Y42: inner_fit_seconds | Z42: outer_fit_seconds | AA42: target_run_seconds | AB42: n_samples | AC42: mae | AD42: rmse | AE42: r2 | AF42: spearman_rho | AG42: bootstrap_repeats | AH42: mae_ci_low | AI42: mae_ci_high | AJ42: rmse_ci_low | AK42: rmse_ci_high | AL42: r2_ci_low | AM42: r2_ci_high | AN42: spearman_rho_ci_low | AO42: spearman_rho_ci_high | AP42: primary_score_bootstrap_valid_repeats | AQ42: primary_score_ci_low | AR42: primary_score_ci_high | AS42: primary_rank_within_target
A43: nested__physiological_features__valence__regression__knn__windowed__hc__emognition_features_w60_o30 | B43: physiological_features | C43: valence | D43: regression | E43: knn__windowed__hc__emognition_features_w60_o30 | F43: 0 | G43: emognition_features_w60_o30 | H43: windowed | I43: hc | J43: knn | K43: trial | L43: 10 | M43: 332 | N43: 42 | O43: 42 | P43: TRUE | Q43: subject_macro_mae | R43: 2.0894255 | S43: 42 | T43: 0 | U43: {"{\"clf__n_neighbors\": 9, \"clf__p\": 2, \"clf__weights\": \"uniform\"}": 42} | V43: {"clf__n_neighbors": 9, "clf__p": 2, "clf__weights": "uniform"} | W43: 1 | X43: FALSE | Y43: 5.6389609 | Z43: 0.3301712 | AA43: 367.16682 | AB43: 332 | AC43: 2.0856555 | AD43: 2.3923745 | AE43: -0.099208613 | AF43: 0.0021979194 | AG43: 1000 | AH43: 1.9101372 | AI43: 2.2700079 | AJ43: 2.2128799 | AK43: 2.5861515 | AL43: -0.17716296 | AM43: -0.031607276 | AN43: -0.10998736 | AO43: 0.11459082 | AP43: 1000 | AQ43: 1.9144563 | AR43: 2.2749243 | AS43: 9
A44: nested__physiological_features__valence__regression__knn__windowed__nvg__emognition_features_w60_o30 | B44: physiological_features | C44: valence | D44: regression | E44: knn__windowed__nvg__emognition_features_w60_o30 | F44: 1 | G44: emognition_features_w60_o30 | H44: windowed | I44: nvg | J44: knn | K44: trial | L44: 10 | M44: 332 | N44: 42 | O44: 42 | P44: TRUE | Q44: subject_macro_mae | R44: 1.9724249 | S44: 42 | T44: 0 | U44: {"{\"clf__n_neighbors\": 9, \"clf__p\": 2, \"clf__weights\": \"uniform\"}": 42} | V44: {"clf__n_neighbors": 9, "clf__p": 2, "clf__weights": "uniform"} | W44: 1 | X44: FALSE | Y44: 6.0039533 | Z44: 0.3727414 | AA44: 393.7386 | AB44: 332 | AC44: 1.9703874 | AD44: 2.2809077 | AE44: 0.00083502324 | AF44: 0.14210654 | AG44: 1000 | AH44: 1.8215222 | AI44: 2.1150884 | AJ44: 2.1232093 | AK44: 2.4262783 | AL44: -0.064766272 | AM44: 0.058382492 | AN44: 0.025601209 | AO44: 0.25811618 | AP44: 1000 | AQ44: 1.825598 | AR44: 2.1166697 | AS44: 1
A45: nested__physiological_features__valence__regression__knn__windowed__hvg__emognition_features_w60_o30 | B45: physiological_features | C45: valence | D45: regression | E45: knn__windowed__hvg__emognition_features_w60_o30 | F45: 2 | G45: emognition_features_w60_o30 | H45: windowed | I45: hvg | J45: knn | K45: trial | L45: 10 | M45: 332 | N45: 42 | O45: 42 | P45: TRUE | Q45: subject_macro_mae | R45: 2.0437226 | S45: 42 | T45: 0 | U45: {"{\"clf__n_neighbors\": 5, \"clf__p\": 2, \"clf__weights\": \"uniform\"}": 2, "{\"clf__n_neighbors\": 9, \"clf__p\": 2, \"clf__weights\": \"distance\"}": 1, "{\"clf__n_neighbors\": 9, \"clf__p\": 2, \"clf__weights\": \"uniform\"}": 39} | V45: {"clf__n_neighbors": 9, "clf__p": 2, "clf__weights": "uniform"} | W45: 0.92857143 | X45: FALSE | Y45: 6.1692548 | Z45: 0.3884101 | AA45: 418.2213 | AB45: 332 | AC45: 2.0433011 | AD45: 2.357076 | AE45: -0.067011177 | AF45: -0.012301973 | AG45: 1000 | AH45: 1.8644073 | AI45: 2.2287076 | AJ45: 2.1795716 | AK45: 2.5366858 | AL45: -0.11481657 | AM45: -0.019349246 | AN45: -0.10499672 | AO45: 0.081014712 | AP45: 1000 | AQ45: 1.8634394 | AR45: 2.2307225 | AS45: 6
A46: nested__physiological_features__valence__regression__knn__windowed__hc+nvg__emognition_features_w60_o30 | B46: physiological_features | C46: valence | D46: regression | E46: knn__windowed__hc+nvg__emognition_features_w60_o30 | F46: 3 | G46: emognition_features_w60_o30 | H46: windowed | I46: hc+nvg | J46: knn | K46: trial | L46: 10 | M46: 332 | N46: 42 | O46: 42 | P46: TRUE | Q46: subject_macro_mae | R46: 2.0049995 | S46: 42 | T46: 0 | U46: {"{\"clf__n_neighbors\": 9, \"clf__p\": 2, \"clf__weights\": \"uniform\"}": 42} | V46: {"clf__n_neighbors": 9, "clf__p": 2, "clf__weights": "uniform"} | W46: 1 | X46: FALSE | Y46: 7.107194 | Z46: 0.4556985 | AA46: 442.71589 | AB46: 332 | AC46: 2.0027038 | AD46: 2.2970017 | AE46: -0.013314835 | AF46: 0.10941629 | AG46: 1000 | AH46: 1.8348705 | AI46: 2.184182 | AJ46: 2.1316845 | AK46: 2.4755405 | AL46: -0.07455954 | AM46: 0.044191103 | AN46: 0.0032051243 | AO46: 0.21405968 | AP46: 1000 | AQ46: 1.8340181 | AR46: 2.1834827 | AS46: 3
A47: nested__physiological_features__valence__regression__knn__windowed__hc+hvg__emognition_features_w60_o30 | B47: physiological_features | C47: valence | D47: regression | E47: knn__windowed__hc+hvg__emognition_features_w60_o30 | F47: 4 | G47: emognition_features_w60_o30 | H47: windowed | I47: hc+hvg | J47: knn | K47: trial | L47: 10 | M47: 332 | N47: 42 | O47: 42 | P47: TRUE | Q47: subject_macro_mae | R47: 2.0895596 | S47: 42 | T47: 0 | U47: {"{\"clf__n_neighbors\": 9, \"clf__p\": 2, \"clf__weights\": \"distance\"}": 23, "{\"clf__n_neighbors\": 9, \"clf__p\": 2, \"clf__weights\": \"uniform\"}": 19} | V47: {"clf__n_neighbors": 9, "clf__p": 2, "clf__weights": "distance"} | W47: 0.54761905 | X47: FALSE | Y47: 7.0159022 | Z47: 0.482716 | AA47: 467.15746 | AB47: 332 | AC47: 2.0892639 | AD47: 2.3885657 | AE47: -0.095711325 | AF47: -0.049615571 | AG47: 1000 | AH47: 1.9244235 | AI47: 2.2451808 | AJ47: 2.2213671 | AK47: 2.5342141 | AL47: -0.16496643 | AM47: -0.045090272 | AN47: -0.15831921 | AO47: 0.048453912 | AP47: 1000 | AQ47: 1.9274759 | AR47: 2.2447089 | AS47: 10
A48: nested__physiological_features__valence__regression__knn__aggregated__hc__emognition_features_w60_o30 | B48: physiological_features | C48: valence | D48: regression | E48: knn__aggregated__hc__emognition_features_w60_o30 | F48: 5 | G48: emognition_features_w60_o30 | H48: aggregated | I48: hc | J48: knn | K48: trial | L48: 10 | M48: 332 | N48: 42 | O48: 42 | P48: TRUE | Q48: subject_macro_mae | R48: 2.053389 | S48: 42 | T48: 0 | U48: {"{\"clf__n_neighbors\": 9, \"clf__p\": 2, \"clf__weights\": \"distance\"}": 31, "{\"clf__n_neighbors\": 9, \"clf__p\": 2, \"clf__weights\": \"uniform\"}": 11} | V48: {"clf__n_neighbors": 9, "clf__p": 2, "clf__weights": "distance"} | W48: 0.73809524 | X48: FALSE | Y48: 5.1811879 | Z48: 0.3571747 | AA48: 491.53578 | AB48: 332 | AC48: 2.0521898 | AD48: 2.3745482 | AE48: -0.082888508 | AF48: 0.037475863 | AG48: 1000 | AH48: 1.8826502 | AI48: 2.2525462 | AJ48: 2.2034284 | AK48: 2.5707307 | AL48: -0.16528207 | AM48: -0.0074735985 | AN48: -0.081221403 | AO48: 0.15102472 | AP48: 1000 | AQ48: 1.8845709 | AR48: 2.2542497 | AS48: 7
A49: nested__physiological_features__valence__regression__knn__aggregated__nvg__emognition_features_w60_o30 | B49: physiological_features | C49: valence | D49: regression | E49: knn__aggregated__nvg__emognition_features_w60_o30 | F49: 6 | G49: emognition_features_w60_o30 | H49: aggregated | I49: nvg | J49: knn | K49: trial | L49: 10 | M49: 332 | N49: 42 | O49: 42 | P49: TRUE | Q49: subject_macro_mae | R49: 1.9909579 | S49: 42 | T49: 0 | U49: {"{\"clf__n_neighbors\": 9, \"clf__p\": 2, \"clf__weights\": \"distance\"}": 31, "{\"clf__n_neighbors\": 9, \"clf__p\": 2, \"clf__weights\": \"uniform\"}": 11} | V49: {"clf__n_neighbors": 9, "clf__p": 2, "clf__weights": "distance"} | W49: 0.73809524 | X49: FALSE | Y49: 5.6956192 | Z49: 0.3933859 | AA49: 515.88767 | AB49: 332 | AC49: 1.9925877 | AD49: 2.3135627 | AE49: -0.027979182 | AF49: 0.16452822 | AG49: 1000 | AH49: 1.8410021 | AI49: 2.1600195 | AJ49: 2.1525087 | AK49: 2.4890487 | AL49: -0.099941725 | AM49: 0.039880878 | AN49: 0.079566367 | AO49: 0.24906397 | AP49: 1000 | AQ49: 1.8396031 | AR49: 2.1569477 | AS49: 2
A50: nested__physiological_features__valence__regression__knn__aggregated__hvg__emognition_features_w60_o30 | B50: physiological_features | C50: valence | D50: regression | E50: knn__aggregated__hvg__emognition_features_w60_o30 | F50: 7 | G50: emognition_features_w60_o30 | H50: aggregated | I50: hvg | J50: knn | K50: trial | L50: 10 | M50: 332 | N50: 42 | O50: 42 | P50: TRUE | Q50: subject_macro_mae | R50: 2.0419646 | S50: 42 | T50: 0 | U50: {"{\"clf__n_neighbors\": 5, \"clf__p\": 2, \"clf__weights\": \"uniform\"}": 6, "{\"clf__n_neighbors\": 9, \"clf__p\": 2, \"clf__weights\": \"distance\"}": 7, "{\"clf__n_neighbors\": 9, \"clf__p\": 2, \"clf__weights\": \"uniform\"}": 29} | V50: {"clf__n_neighbors": 9, "clf__p": 2, "clf__weights": "uniform"} | W50: 0.69047619 | X50: FALSE | Y50: 5.5967884 | Z50: 0.4020845 | AA50: 540.34775 | AB50: 332 | AC50: 2.0441112 | AD50: 2.3696069 | AE50: -0.078386415 | AF50: 0.10516727 | AG50: 1000 | AH50: 1.8755907 | AI50: 2.2009322 | AJ50: 2.1973489 | AK50: 2.5256264 | AL50: -0.17396836 | AM50: 0.0014571728 | AN50: 0.0025328626 | AO50: 0.20398083 | AP50: 1000 | AQ50: 1.8738762 | AR50: 2.2026055 | AS50: 5
A51: nested__physiological_features__valence__regression__knn__aggregated__hc+nvg__emognition_features_w60_o30 | B51: physiological_features | C51: valence | D51: regression | E51: knn__aggregated__hc+nvg__emognition_features_w60_o30 | F51: 8 | G51: emognition_features_w60_o30 | H51: aggregated | I51: hc+nvg | J51: knn | K51: trial | L51: 10 | M51: 332 | N51: 42 | O51: 42 | P51: TRUE | Q51: subject_macro_mae | R51: 2.0144854 | S51: 42 | T51: 0 | U51: {"{\"clf__n_neighbors\": 9, \"clf__p\": 2, \"clf__weights\": \"distance\"}": 27, "{\"clf__n_neighbors\": 9, \"clf__p\": 2, \"clf__weights\": \"uniform\"}": 15} | V51: {"clf__n_neighbors": 9, "clf__p": 2, "clf__weights": "distance"} | W51: 0.64285714 | X51: FALSE | Y51: 6.5080777 | Z51: 0.46896 | AA51: 564.78752 | AB51: 332 | AC51: 2.0162419 | AD51: 2.3527622 | AE51: -0.06310911 | AF51: 0.10114366 | AG51: 1000 | AH51: 1.8498913 | AI51: 2.1892157 | AJ51: 2.1920803 | AK51: 2.5250595 | AL51: -0.13718384 | AM51: 0.010821998 | AN51: 0.0066780234 | AO51: 0.20154286 | AP51: 1000 | AQ51: 1.8479752 | AR51: 2.1839606 | AS51: 4
A52: nested__physiological_features__valence__regression__knn__aggregated__hc+hvg__emognition_features_w60_o30 | B52: physiological_features | C52: valence | D52: regression | E52: knn__aggregated__hc+hvg__emognition_features_w60_o30 | F52: 9 | G52: emognition_features_w60_o30 | H52: aggregated | I52: hc+hvg | J52: knn | K52: trial | L52: 10 | M52: 332 | N52: 42 | O52: 42 | P52: TRUE | Q52: subject_macro_mae | R52: 2.0595236 | S52: 42 | T52: 0 | U52: {"{\"clf__n_neighbors\": 9, \"clf__p\": 2, \"clf__weights\": \"distance\"}": 39, "{\"clf__n_neighbors\": 9, \"clf__p\": 2, \"clf__weights\": \"uniform\"}": 3} | V52: {"clf__n_neighbors": 9, "clf__p": 2, "clf__weights": "distance"} | W52: 0.92857143 | X52: FALSE | Y52: 6.4337651 | Z52: 0.4998704 | AA52: 589.18099 | AB52: 332 | AC52: 2.0592696 | AD52: 2.3878823 | AE52: -0.095084476 | AF52: 0.058130195 | AG52: 1000 | AH52: 1.8955979 | AI52: 2.2286762 | AJ52: 2.2205557 | AK52: 2.5456437 | AL52: -0.1645758 | AM52: -0.038924027 | AN52: -0.01959265 | AO52: 0.1336089 | AP52: 1000 | AQ52: 1.8968081 | AR52: 2.2303332 | AS52: 8
A53: nested__physiological_features__arousal__regression__knn__windowed__hc__emognition_features_w60_o30 | B53: physiological_features | C53: arousal | D53: regression | E53: knn__windowed__hc__emognition_features_w60_o30 | F53: 0 | G53: emognition_features_w60_o30 | H53: windowed | I53: hc | J53: knn | K53: trial | L53: 10 | M53: 332 | N53: 42 | O53: 42 | P53: TRUE | Q53: subject_macro_mae | R53: 1.9056871 | S53: 42 | T53: 0 | U53: {"{\"clf__n_neighbors\": 9, \"clf__p\": 2, \"clf__weights\": \"distance\"}": 7, "{\"clf__n_neighbors\": 9, \"clf__p\": 2, \"clf__weights\": \"uniform\"}": 35} | V53: {"clf__n_neighbors": 9, "clf__p": 2, "clf__weights": "uniform"} | W53: 0.83333333 | X53: FALSE | Y53: 5.6187658 | Z53: 0.3426604 | AA53: 356.61566 | AB53: 332 | AC53: 1.9045375 | AD53: 2.2429924 | AE53: -0.26237201 | AF53: -0.20727556 | AG53: 1000 | AH53: 1.7361298 | AI53: 2.0833834 | AJ53: 2.0581234 | AK53: 2.4237143 | AL53: -0.40999223 | AM53: -0.16143242 | AN53: -0.35960931 | AO53: -0.056309507 | AP53: 1000 | AQ53: 1.740404 | AR53: 2.0821085 | AS53: 10
A54: nested__physiological_features__arousal__regression__knn__windowed__nvg__emognition_features_w60_o30 | B54: physiological_features | C54: arousal | D54: regression | E54: knn__windowed__nvg__emognition_features_w60_o30 | F54: 1 | G54: emognition_features_w60_o30 | H54: windowed | I54: nvg | J54: knn | K54: trial | L54: 10 | M54: 332 | N54: 42 | O54: 42 | P54: TRUE | Q54: subject_macro_mae | R54: 1.7640584 | S54: 42 | T54: 0 | U54: {"{\"clf__n_neighbors\": 9, \"clf__p\": 2, \"clf__weights\": \"distance\"}": 15, "{\"clf__n_neighbors\": 9, \"clf__p\": 2, \"clf__weights\": \"uniform\"}": 27} | V54: {"clf__n_neighbors": 9, "clf__p": 2, "clf__weights": "uniform"} | W54: 0.64285714 | X54: FALSE | Y54: 6.2470709 | Z54: 0.3969261 | AA54: 381.04977 | AB54: 332 | AC54: 1.7603492 | AD54: 2.0756221 | AE54: -0.081006596 | AF54: 0.0064420922 | AG54: 1000 | AH54: 1.6187851 | AI54: 1.9051195 | AJ54: 1.9353384 | AK54: 2.21234 | AL54: -0.19741002 | AM54: -0.015240932 | AN54: -0.10457367 | AO54: 0.12905673 | AP54: 1000 | AQ54: 1.6208615 | AR54: 1.9107656 | AS54: 4
...

Sheet Results
BP1: # | BQ1: Win | BR1: # | BS1: Mode | BT1: # | BU1: Target | BV1: # | BW1: Type | BX1: # | BY1: Color scale | BZ1: # | CA1: Classification
B2: Window / Overlap | C2: 1 | D2: =VLOOKUP(C2,Win,2,0) -> w60_o30 | BP2: 1 | BQ2: w60_o30 | BR2: 1 | BS2: windowed | BT2: 1 | BU2: valence | BV2: 1 | BW2: input/model | BX2: 1 | BY2: no | BZ2: 1 | CA2: binary
BP3: 2 | BQ3: w60_o15 | BR3: 2 | BS3: aggregated | BT3: 2 | BU3: arousal | BV3: 2 | BW3: best overall | BX3: 2 | BY3: accuracy/mae | BZ3: 2 | CA3: ternary
B4: Input Mode | C4: 2 | D4: =VLOOKUP(C4,InputMode,2,0) -> aggregated | BP4: 3 | BQ4: w60_o0 | BX4: 3 | BY4: recall/rmse | BZ4: 3 | CA4: regression
BP5: 4 | BQ5: w45_o22p5 | BX5: 4 | BY5: precision/r2
B6: Target | C6: 2 | D6: =VLOOKUP(C6,Target,2,0) -> arousal | BP6: 5 | BQ6: w45_o11p25 | BX6: 5 | BY6: f1/primary score
BP7: 6 | BQ7: w45_o0
B8: Best Comparison | C8: 2 | BP8: 7 | BQ8: w30_o15
BP9: 8 | BQ9: w30_o7p5
B10: Color Scale | C10: 2 | BP10: 9 | BQ10: w30_o0
B12: Classification | C12: 2 | D12: =VLOOKUP(C12,Class,2,0) -> ternary
B14: Model | C14: Code | D14: HC | L14: NVG | T14: HVG | AB14: HC+NVG | AJ14: HC+HVG
